Workbook

Sheet RÉCAP
A1: BINGO 2026 | J1: BINGO 2025 | S1: BINGO 2024 | AB1: BINGO 2023
A2: N° | B2: Date | C2: N1 | D2: N2 | E2: N3 | F2: N4 | G2: N5 | H2: TOTAL | J2: N° | K2: Date | L2: N1 | M2: N2 | N2: N3 | O2: N4 | P2: N5 | Q2: TOTAL | S2: N° | T2: Date | U2: N1 | V2: N2 | W2: N3 | X2: N4 | Y2: N5 | Z2: TOTAL | AB2: N° | AC2: Date | AD2: N1 | AE2: N2 | AF2: N3 | AG2: N4 | AH2: N5 | AI2: TOTAL
A3: BINGO132 | B3: 3/1/2026 | C3: 42 | D3: 7 | E3: 79 | F3: 24 | G3: 57 | H3: =SUM(C3:G3) -> 209 | J3: BINGO080 | K3: 4/1/2025 | L3: 49 | M3: 37 | N3: 83 | O3: 80 | P3: 34 | Q3: =SUM(L3:P3) -> 283 | S3: BINGO028 | T3: 6/1/2024 | U3: 46 | V3: 34 | W3: 50 | X3: 40 | Y3: 51 | Z3: =SUM(U3:Y3) -> 221 | AB3: BINGO001 | AC3: 1/7/2023 | AD3: 67 | AE3: 6 | AF3: 90 | AG3: 72 | AH3: 47 | AI3: =SUM(AD3:AH3) -> 282
A4: BINGO133 | B4: 10/1/2026 | C4: 17 | D4: 75 | E4: 11 | F4: 82 | G4: 23 | H4: =SUM(C4:G4) -> 208 | J4: BINGO081 | K4: 11/1/2025 | L4: 31 | M4: 32 | N4: 71 | O4: 75 | P4: 90 | Q4: =SUM(L4:P4) -> 299 | S4: BINGO029 | T4: 13/1/2024 | U4: 86 | V4: 45 | W4: 35 | X4: 22 | Y4: 26 | Z4: =SUM(U4:Y4) -> 214 | AB4: BINGO002 | AC4: 8/7/2023 | AD4: 82 | AE4: 55 | AF4: 31 | AG4: 34 | AH4: 86 | AI4: =SUM(AD4:AH4) -> 288
A5: BINGO134 | B5: 17/1/2026 | C5: 13 | D5: 76 | E5: 53 | F5: 57 | G5: 68 | H5: =SUM(C5:G5) -> 267 | J5: BINGO082 | K5: 18/1/2025 | L5: 12 | M5: 27 | N5: 48 | O5: 35 | P5: 9 | Q5: =SUM(L5:P5) -> 131 | S5: BINGO030 | T5: 20/1/2024 | U5: 79 | V5: 82 | W5: 6 | X5: 68 | Y5: 64 | Z5: =SUM(U5:Y5) -> 299 | AB5: BINGO003 | AC5: 15/7/2023 | AD5: 28 | AE5: 37 | AF5: 58 | AG5: 64 | AH5: 52 | AI5: =SUM(AD5:AH5) -> 239
A6: BINGO135 | B6: 24/1/2026 | C6: 18 | D6: 26 | E6: 68 | F6: 54 | G6: 64 | H6: =SUM(C6:G6) -> 230 | J6: BINGO083 | K6: 25/1/2025 | L6: 16 | M6: 54 | N6: 37 | O6: 1 | P6: 32 | Q6: =SUM(L6:P6) -> 140 | S6: BINGO031 | T6: 27/1/2024 | U6: 26 | V6: 12 | W6: 49 | X6: 55 | Y6: 42 | Z6: =SUM(U6:Y6) -> 184 | AB6: BINGO004 | AC6: 22/7/2023 | AD6: 31 | AE6: 52 | AF6: 77 | AG6: 13 | AH6: 33 | AI6: =SUM(AD6:AH6) -> 206
A7: BINGO136 | B7: 31/1/2026 | C7: 49 | D7: 77 | E7: 41 | F7: 5 | G7: 70 | H7: =SUM(C7:G7) -> 242 | J7: BINGO084 | K7: 1/2/2025 | L7: 64 | M7: 71 | N7: 29 | O7: 18 | P7: 34 | Q7: =SUM(L7:P7) -> 216 | S7: BINGO032 | T7: 3/2/2024 | U7: 2 | V7: 85 | W7: 82 | X7: 42 | Y7: 55 | Z7: =SUM(U7:Y7) -> 266 | AB7: BINGO005 | AC7: 29/7/2023 | AD7: 33 | AE7: 4 | AF7: 12 | AG7: 22 | AH7: 58 | AI7: =SUM(AD7:AH7) -> 129
A8: BINGO137 | B8: 7/2/2026 | C8: 45 | D8: 16 | E8: 9 | F8: 11 | G8: 15 | H8: =SUM(C8:G8) -> 96 | J8: BINGO085 | K8: 8/2/2025 | L8: 51 | M8: 30 | N8: 44 | O8: 47 | P8: 19 | Q8: =SUM(L8:P8) -> 191 | S8: BINGO033 | T8: 10/2/2024 | U8: 3 | V8: 47 | W8: 2 | X8: 43 | Y8: 46 | Z8: =SUM(U8:Y8) -> 141 | AB8: BINGO006 | AC8: 5/8/2023 | AD8: 63 | AE8: 1 | AF8: 35 | AG8: 86 | AH8: 55 | AI8: =SUM(AD8:AH8) -> 240
A9: BINGO138 | B9: 14/2/2026 | C9: 30 | D9: 39 | E9: 43 | F9: 86 | G9: 15 | H9: =SUM(C9:G9) -> 213 | J9: BINGO086 | K9: 15/2/2025 | L9: 77 | M9: 11 | N9: 47 | O9: 67 | P9: 23 | Q9: =SUM(L9:P9) -> 225 | S9: BINGO034 | T9: 17/2/2024 | U9: 40 | V9: 23 | W9: 41 | X9: 81 | Y9: 39 | Z9: =SUM(U9:Y9) -> 224 | AB9: BINGO007 | AC9: 12/8/2023 | AD9: 2 | AE9: 76 | AF9: 9 | AG9: 22 | AH9: 48 | AI9: =SUM(AD9:AH9) -> 157
A10: BINGO139 | B10: 21/2/2026 | C10: 10 | D10: 72 | E10: 5 | F10: 54 | G10: 38 | H10: =SUM(C10:G10) -> 179 | J10: BINGO087 | K10: 22/2/2025 | L10: 55 | M10: 34 | N10: 39 | O10: 23 | P10: 17 | Q10: =SUM(L10:P10) -> 168 | S10: BINGO035 | T10: 24/2/2024 | U10: 70 | V10: 51 | W10: 32 | X10: 53 | Y10: 9 | Z10: =SUM(U10:Y10) -> 215 | AB10: BINGO008 | AC10: 19/8/2023 | AD10: 27 | AE10: 89 | AF10: 59 | AG10: 49 | AH10: 46 | AI10: =SUM(AD10:AH10) -> 270
A11: BINGO140 | B11: 28/2/2026 | C11: 67 | D11: 76 | E11: 47 | F11: 60 | G11: 18 | H11: =SUM(C11:G11) -> 268 | J11: BINGO088 | K11: 1/3/2025 | L11: 1 | M11: 76 | N11: 25 | O11: 69 | P11: 68 | Q11: =SUM(L11:P11) -> 239 | S11: BINGO036 | T11: 2/3/2024 | U11: 22 | V11: 24 | W11: 37 | X11: 36 | Y11: 33 | Z11: =SUM(U11:Y11) -> 152 | AB11: BINGO009 | AC11: 26/8/2023 | AD11: 15 | AE11: 87 | AF11: 23 | AG11: 14 | AH11: 74 | AI11: =SUM(AD11:AH11) -> 213
A12: BINGO141 | B12: 7/3/2026 | C12: 70 | D12: 24 | E12: 8 | F12: 43 | G12: 28 | H12: =SUM(C12:G12) -> 173 | J12: BINGO089 | K12: 8/3/2025 | L12: 72 | M12: 30 | N12: 13 | O12: 56 | P12: 33 | Q12: =SUM(L12:P12) -> 204 | S12: BINGO037 | T12: 9/3/2024 | U12: 87 | V12: 35 | W12: 29 | X12: 21 | Y12: 13 | Z12: =SUM(U12:Y12) -> 185 | AB12: BINGO010 | AC12: 2/9/2023 | AD12: 7 | AE12: 69 | AF12: 20 | AG12: 25 | AH12: 66 | AI12: =SUM(AD12:AH12) -> 187
A13: BINGO142 | B13: 14/3/2026 | C13: 32 | D13: 31 | E13: 55 | F13: 83 | G13: 45 | H13: =SUM(C13:G13) -> 246 | J13: BINGO090 | K13: 15/3/2025 | L13: 78 | M13: 35 | N13: 12 | O13: 80 | P13: 77 | Q13: =SUM(L13:P13) -> 282 | S13: BINGO038 | T13: 16/3/2024 | U13: 19 | V13: 7 | W13: 3 | X13: 83 | Y13: 87 | Z13: =SUM(U13:Y13) -> 199 | AB13: BINGO011 | AC13: 9/9/2023 | AD13: 9 | AE13: 35 | AF13: 45 | AG13: 32 | AH13: 52 | AI13: =SUM(AD13:AH13) -> 173
A14: BINGO143 | B14: 21/3/2026 | C14: 1 | D14: 12 | E14: 81 | F14: 35 | G14: 62 | H14: =SUM(C14:G14) -> 191 | J14: BINGO091 | K14: 22/3/2025 | L14: 29 | M14: 46 | N14: 13 | O14: 4 | P14: 27 | Q14: =SUM(L14:P14) -> 119 | S14: BINGO039 | T14: 23/3/2024 | U14: 6 | V14: 55 | W14: 83 | X14: 10 | Y14: 51 | Z14: =SUM(U14:Y14) -> 205 | AB14: BINGO012 | AC14: 16/9/2023 | AD14: 88 | AE14: 14 | AF14: 9 | AG14: 70 | AH14: 21 | AI14: =SUM(AD14:AH14) -> 202
... A29: BINGO158 | B29: 4/7/2026 | C29: 31 | D29: 72 | E29: 20 | F29: 1 | G29: 24 | H29: =SUM(C29:G29) -> 148 | J29: BINGO106 | K29: 5/7/2025 | L29: 28 | M29: 45 | N29: 21 | O29: 69 | P29: 48 | Q29: =SUM(L29:P29) -> 211 | S29: BINGO054 | T29: 6/7/2024 | U29: 56 | V29: 25 | W29: 13 | X29: 76 | Y29: 23 | Z29: =SUM(U29:Y29) -> 193 | AB29: BINGO027 | AC29: 30/12/2023 | AD29: 46 | AE29: 26 | AF29: 8 | AG29: 38 | AH29: 25 | AI29: =SUM(AD29:AH29) -> 143
J30: BINGO107 | K30: 12/7/2025 | L30: 66 | M30: 63 | N30: 11 | O30: 28 | P30: 9 | Q30: =SUM(L30:P30) -> 177 | S30: BINGO055 | T30: 13/7/2024 | U30: 14 | V30: 57 | W30: 53 | X30: 13 | Y30: 49 | Z30: =SUM(U30:Y30) -> 186
J31: BINGO108 | K31: 19/7/2025 | L31: 80 | M31: 38 | N31: 60 | O31: 42 | P31: 68 | Q31: =SUM(L31:P31) -> 288 | S31: BINGO056 | T31: 20/7/2024 | U31: 73 | V31: 5 | W31: 24 | X31: 10 | Y31: 64 | Z31: =SUM(U31:Y31) -> 176
J32: BINGO109 | K32: 26/7/2025 | L32: 36 | M32: 51 | N32: 76 | O32: 32 | P32: 29 | Q32: =SUM(L32:P32) -> 224 | S32: BINGO057 | T32: 27/7/2024 | U32: 78 | V32: 34 | W32: 8 | X32: 46 | Y32: 69 | Z32: =SUM(U32:Y32) -> 235
J33: BINGO110 | K33: 2/8/2025 | L33: 52 | M33: 15 | N33: 19 | O33: 61 | P33: 34 | Q33: =SUM(L33:P33) -> 181 | S33: BINGO058 | T33: 3/8/2024 | U33: 58 | V33: 42 | W33: 66 | X33: 69 | Y33: 60 | Z33: =SUM(U33:Y33) -> 295
J34: BINGO111 | K34: 9/8/2025 | L34: 60 | M34: 68 | N34: 57 | O34: 72 | P34: 22 | Q34: =SUM(L34:P34) -> 279 | S34: BINGO059 | T34: 10/8/2024 | U34: 34 | V34: 45 | W34: 81 | X34: 61 | Y34: 46 | Z34: =SUM(U34:Y34) -> 267
J35: BINGO112 | K35: 16/8/2025 | L35: 6 | M35: 46 | N35: 53 | O35: 70 | P35: 65 | Q35: =SUM(L35:P35) -> 240 | S35: BINGO060 | T35: 17/8/2024 | U35: 14 | V35: 81 | W35: 2 | X35: 13 | Y35: 76 | Z35: =SUM(U35:Y35) -> 186
J36: BINGO113 | K36: 23/8/2025 | L36: 43 | M36: 80 | N36: 29 | O36: 14 | P36: 62 | Q36: =SUM(L36:P36) -> 228 | S36: BINGO061 | T36: 24/8/2024 | U36: 36 | V36: 3 | W36: 54 | X36: 24 | Y36: 43 | Z36: =SUM(U36:Y36) -> 160
J37: BINGO114 | K37: 30/8/2025 | L37: 9 | M37: 80 | N37: 82 | O37: 58 | P37: 21 | Q37: =SUM(L37:P37) -> 250 | S37: BINGO062 | T37: 31/8/2024 | U37: 50 | V37: 37 | W37: 76 | X37: 31 | Y37: 6 | Z37: =SUM(U37:Y37) -> 200
J38: BINGO115 | K38: 6/9/2025 | L38: 62 | M38: 23 | N38: 45 | O38: 41 | P38: 54 | Q38: =SUM(L38:P38) -> 225 | S38: BINGO063 | T38: 7/9/2024 | U38: 30 | V38: 86 | W38: 67 | X38: 4 | Y38: 72 | Z38: =SUM(U38:Y38) -> 259
J39: BINGO116 | K39: 13/9/2025 | L39: 35 | M39: 38 | N39: 6 | O39: 23 | P39: 7 | Q39: =SUM(L39:P39) -> 109 | S39: BINGO064 | T39: 14/9/2024 | U39: 84 | V39: 61 | W39: 45 | X39: 52 | Y39: 65 | Z39: =SUM(U39:Y39) -> 307
J40: BINGO117 | K40: 20/9/2025 | L40: 4 | M40: 81 | N40: 31 | O40: 45 | P40: 51 | Q40: =SUM(L40:P40) -> 212 | S40: BINGO065 | T40: 21/9/2024 | U40: 23 | V40: 42 | W40: 17 | X40: 41 | Y40: 8 | Z40: =SUM(U40:Y40) -> 131
J41: BINGO118 | K41: 27/9/2025 | L41: 3 | M41: 23 | N41: 69 | O41: 24 | P41: 2 | Q41: =SUM(L41:P41) -> 121 | S41: BINGO066 | T41: 28/9/2024 | U41: 58 | V41: 41 | W41: 5 | X41: 88 | Y41: 13 | Z41: =SUM(U41:Y41) -> 205
... J54: BINGO131 | K54: 27/12/2025 | L54: 63 | M54: 27 | N54: 85 | O54: 32 | P54: 46 | Q54: =SUM(L54:P54) -> 253 | S54: BINGO079 | T54: 28/12/2024 | U54: 29 | V54: 38 | W54: 57 | X54: 90 | Y54: 31 | Z54: =SUM(U54:Y54) -> 245

Sheet BINGO 2026
A1: BINGO 2026 | M1: BINGO 2026
A2: N° | B2: Date | C2: N1 | D2: N2 | E2: N3 | F2: N4 | G2: N5 | H2: TOTAL | M2: N° | N2: Date | O2: N1 | P2: N2 | Q2: N3 | R2: N4 | S2: N5 | T2: TOTAL
A3: BINGO132 | B3: 3/1/2026 | C3: 42 | D3: 7 | E3: 79 | F3: 24 | G3: 57 | H3: =SUM(C3:G3) -> 209 | M3: BINGO132 | N3: 3/1/2026 | O3: 42 | P3: 7 | Q3: 79 | R3: 24 | S3: 57 | T3: =SUM(O3:S3) -> 209
A4: BINGO133 | B4: 10/1/2026 | C4: 17 | D4: 75 | E4: 11 | F4: 82 | G4: 23 | H4: =SUM(C4:G4) -> 208 | M4: BINGO133 | N4: 10/1/2026 | O4: 17 | P4: 75 | Q4: 11 | R4: 82 | S4: 23 | T4: =SUM(O4:S4) -> 208
A5: BINGO134 | B5: 17/1/2026 | C5: 13 | D5: 76 | E5: 53 | F5: 57 | G5: 68 | H5: =SUM(C5:G5) -> 267 | M5: BINGO134 | N5: 17/1/2026 | O5: 13 | P5: 76 | Q5: 53 | R5: 57 | S5: 68 | T5: =SUM(O5:S5) -> 267
A6: BINGO135 | B6: 24/1/2026 | C6: 18 | D6: 26 | E6: 68 | F6: 54 | G6: 64 | H6: =SUM(C6:G6) -> 230 | M6: BINGO135 | N6: 24/1/2026 | O6: 18 | P6: 26 | Q6: 68 | R6: 54 | S6: 64 | T6: =SUM(O6:S6) -> 230
A7: BINGO136 | B7: 31/1/2026 | C7: 49 | D7: 77 | E7: 41 | F7: 5 | G7: 70 | H7: =SUM(C7:G7) -> 242 | M7: BINGO136 | N7: 31/1/2026 | O7: 49 | P7: 77 | Q7: 41 | R7: 5 | S7: 70 | T7: =SUM(O7:S7) -> 242
A8: BINGO137 | B8: 7/2/2026 | C8: 45 | D8: 16 | E8: 9 | F8: 11 | G8: 15 | H8: =SUM(C8:G8) -> 96 | M8: BINGO137 | N8: 7/2/2026 | O8: 45 | P8: 16 | Q8: 9 | R8: 11 | S8: 15 | T8: =SUM(O8:S8) -> 96
A9: BINGO138 | B9: 14/2/2026 | C9: 30 | D9: 39 | E9: 43 | F9: 86 | G9: 15 | H9: =SUM(C9:G9) -> 213 | M9: BINGO138 | N9: 14/2/2026 | O9: 30 | P9: 39 | Q9: 43 | R9: 86 | S9: 15 | T9: =SUM(O9:S9) -> 213
A10: BINGO139 | B10: 21/2/2026 | C10: 10 | D10: 72 | E10: 5 | F10: 54 | G10: 38 | H10: =SUM(C10:G10) -> 179 | M10: BINGO139 | N10: 21/2/2026 | O10: 10 | P10: 72 | Q10: 5 | R10: 54 | S10: 38 | T10: =SUM(O10:S10) -> 179
A11: BINGO140 | B11: 28/2/2026 | C11: 67 | D11: 76 | E11: 47 | F11: 60 | G11: 18 | H11: =SUM(C11:G11) -> 268 | M11: BINGO140 | N11: 28/2/2026 | O11: 67 | P11: 76 | Q11: 47 | R11: 60 | S11: 18 | T11: =SUM(O11:S11) -> 268
A12: BINGO141 | B12: 7/3/2026 | C12: 70 | D12: 24 | E12: 8 | F12: 43 | G12: 28 | H12: =SUM(C12:G12) -> 173 | M12: BINGO141 | N12: 7/3/2026 | O12: 70 | P12: 24 | Q12: 8 | R12: 43 | S12: 28 | T12: =SUM(O12:S12) -> 173
A13: BINGO142 | B13: 14/3/2026 | C13: 32 | D13: 31 | E13: 55 | F13: 83 | G13: 45 | H13: =SUM(C13:G13) -> 246 | M13: BINGO142 | N13: 14/3/2026 | O13: 32 | P13: 31 | Q13: 55 | R13: 83 | S13: 45 | T13: =SUM(O13:S13) -> 246
A14: BINGO143 | B14: 21/3/2026 | C14: 1 | D14: 12 | E14: 81 | F14: 35 | G14: 62 | H14: =SUM(C14:G14) -> 191 | M14: BINGO143 | N14: 21/3/2026 | O14: 1 | P14: 12 | Q14: 81 | R14: 35 | S14: 62 | T14: =SUM(O14:S14) -> 191
... A29: BINGO158 | B29: 4/7/2026 | C29: 31 | D29: 72 | E29: 20 | F29: 1 | G29: 24 | H29: =SUM(C29:G29) -> 148 | M29: BINGO158 | N29: 4/7/2026 | O29: 31 | P29: 72 | Q29: 20 | R29: 1 | S29: 24 | T29: =SUM(O29:S29) -> 148
M30: 511 | N30: 8/7 | O30: 26 | P30: 42 | Q30: 40 | R30: 38 | S30: 30 | T30: =O30+P30+Q30+R30+S30 -> 176
M31: 512 | N31: 15/7 | O31: 29 | P31: 84 | Q31: 74 | R31: 3 | S31: 88 | T31: =O31+P31+Q31+R31+S31 -> 278
A32: Statistiques 2026 | M32: 513 | N32: 22/7 | O32: 76 | P32: 17 | Q32: 58 | R32: 32 | S32: 89 | T32: =O32+P32+Q32+R32+S32 -> 272
A33: Nombre de tirages | M33: 514 | N33: 29/7 | O33: 57 | P33: 52 | Q33: 7 | R33: 25 | S33: 9 | T33: =O33+P33+Q33+R33+S33 -> 150
A34: Total général | M34: 515 | N34: 5/8 | O34: 78 | P34: 41 | Q34: 74 | R34: 10 | S34: 11 | T34: =O34+P34+Q34+R34+S34 -> 214
A35: Moyenne TOTAL | M35: 516 | N35: 12/8 | O35: 25 | P35: 26 | Q35: 58 | R35: 6 | S35: 88 | T35: =O35+P35+Q35+R35+S35 -> 203
A36: TOTAL max | M36: 517 | N36: 19/8 | O36: 47 | P36: 31 | Q36: 59 | R36: 82 | S36: 67 | T36: =O36+P36+Q36+R36+S36 -> 286
A37: TOTAL min | M37: 518 | N37: 26/8 | O37: 26 | P37: 32 | Q37: 35 | R37: 39 | S37: 86 | T37: =O37+P37+Q37+R37+S37 -> 218
A38: Moyenne N1 | M38: 519 | N38: 2/9 | O38: 74 | P38: 17 | Q38: 4 | R38: 88 | S38: 53 | T38: =O38+P38+Q38+R38+S38 -> 236
A39: Moyenne N2 | M39: 520 | N39: 9/9 | O39: 7 | P39: 69 | Q39: 43 | R39: 48 | S39: 53 | T39: =O39+P39+Q39+R39+S39 -> 220
A40: Moyenne N3 | M40: 521 | N40: 16/9 | O40: 9 | P40: 23 | Q40: 39 | R40: 85 | S40: 40 | T40: =O40+P40+Q40+R40+S40 -> 196
A41: Moyenne N4 | M41: 522 | N41: 23/9 | O41: 18 | P41: 74 | Q41: 22 | R41: 19 | S41: 1 | T41: =O41+P41+Q41+R41+S41 -> 134
A42: Moyenne N5 | M42: 523 | N42: 30/9 | O42: 84 | P42: 54 | Q42: 20 | R42: 22 | S42: 5 | T42: =O42+P42+Q42+R42+S42 -> 185
M43: 524 | N43: 7/10 | O43: 86 | P43: 66 | Q43: 4 | R43: 58 | S43: 5 | T43: =O43+P43+Q43+R43+S43 -> 219
M44: 525 | N44: 14/10 | O44: 87 | P44: 43 | Q44: 15 | R44: 61 | S44: 37 | T44: =O44+P44+Q44+R44+S44 -> 243
M45: 526 | N45: 21/10 | O45: 49 | P45: 31 | Q45: 47 | R45: 56 | S45: 82 | T45: =O45+P45+Q45+R45+S45 -> 265
M46: 527 | N46: 28/10 | O46: 9 | P46: 41 | Q46: 25 | R46: 26 | S46: 32 | T46: =O46+P46+Q46+R46+S46 -> 133
M47: 528 | N47: 4/11 | O47: 53 | P47: 9 | Q47: 49 | R47: 64 | S47: 17 | T47: =O47+P47+Q47+R47+S47 -> 192
M48: 529 | N48: 11/11 | O48: 58 | P48: 74 | Q48: 15 | R48: 12 | S48: 80 | T48: =O48+P48+Q48+R48+S48 -> 239
M49: 530 | N49: 18/11 | O49: 79 | P49: 40 | Q49: 38 | R49: 63 | S49: 50 | T49: =O49+P49+Q49+R49+S49 -> 270
M50: 531 | N50: 25/11 | O50: 48 | P50: 21 | Q50: 83 | R50: 53 | S50: 50 | T50: =O50+P50+Q50+R50+S50 -> 255
M51: 532 | N51: 2/12 | O51: 12 | P51: 24 | Q51: 32 | R51: 45 | S51: 63 | T51: =O51+P51+Q51+R51+S51 -> 176
M52: 533 | N52: 9/12 | O52: 54 | P52: 41 | Q52: 53 | R52: 83 | S52: 80 | T52: =O52+P52+Q52+R52+S52 -> 311
M53: 534 | N53: 16/12 | O53: 16 | P53: 2 | Q53: 45 | R53: 53 | S53: 88 | T53: =O53+P53+Q53+R53+S53 -> 204
M54: 535 | N54: 23/12 | O54: 85 | P54: 74 | Q54: 65 | R54: 33 | S54: 54 | T54: =O54+P54+Q54+R54+S54 -> 311
...

Sheet BINGO 2025
A1: BINGO 2025
A2: N° | B2: Date | C2: N1 | D2: N2 | E2: N3 | F2: N4 | G2: N5 | H2: TOTAL
A3: BINGO080 | B3: 4/1/2025 | C3: 49 | D3: 37 | E3: 83 | F3: 80 | G3: 34 | H3: =SUM(C3:G3) -> 283
A4: BINGO081 | B4: 11/1/2025 | C4: 31 | D4: 32 | E4: 71 | F4: 75 | G4: 90 | H4: =SUM(C4:G4) -> 299
A5: BINGO082 | B5: 18/1/2025 | C5: 12 | D5: 27 | E5: 48 | F5: 35 | G5: 9 | H5: =SUM(C5:G5) -> 131
A6: BINGO083 | B6: 25/1/2025 | C6: 16 | D6: 54 | E6: 37 | F6: 1 | G6: 32 | H6: =SUM(C6:G6) -> 140
A7: BINGO084 | B7: 1/2/2025 | C7: 64 | D7: 71 | E7: 29 | F7: 18 | G7: 34 | H7: =SUM(C7:G7) -> 216
A8: BINGO085 | B8: 8/2/2025 | C8: 51 | D8: 30 | E8: 44 | F8: 47 | G8: 19 | H8: =SUM(C8:G8) -> 191
A9: BINGO086 | B9: 15/2/2025 | C9: 77 | D9: 11 | E9: 47 | F9: 67 | G9: 23 | H9: =SUM(C9:G9) -> 225
A10: BINGO087 | B10: 22/2/2025 | C10: 55 | D10: 34 | E10: 39 | F10: 23 | G10: 17 | H10: =SUM(C10:G10) -> 168
A11: BINGO088 | B11: 1/3/2025 | C11: 1 | D11: 76 | E11: 25 | F11: 69 | G11: 68 | H11: =SUM(C11:G11) -> 239
A12: BINGO089 | B12: 8/3/2025 | C12: 72 | D12: 30 | E12: 13 | F12: 56 | G12: 33 | H12: =SUM(C12:G12) -> 204
A13: BINGO090 | B13: 15/3/2025 | C13: 78 | D13: 35 | E13: 12 | F13: 80 | G13: 77 | H13: =SUM(C13:G13) -> 282
A14: BINGO091 | B14: 22/3/2025 | C14: 29 | D14: 46 | E14: 13 | F14: 4 | G14: 27 | H14: =SUM(C14:G14) -> 119
... A54: BINGO131 | B54: 27/12/2025 | C54: 63 | D54: 27 | E54: 85 | F54: 32 | G54: 46 | H54: =SUM(C54:G54) -> 253
A57: Statistiques 2025
A58: Nombre de tirages
A59: Total général
A60: Moyenne TOTAL
A61: TOTAL max
A62: TOTAL min
A63: Moyenne N1
A64: Moyenne N2
A65: Moyenne N3
A66: Moyenne N4
A67: Moyenne N5

Sheet Feuil3
A1: NATIONAL WEEK — GHANA
A2: Tirage hebdomadaire (samedi) — 5 numéros gagnants + 5 numéros machine — TOT = somme des 5 gagnants — Trio 42·24·57 surligné en violet
A4: NATIONAL WEEK 2001 | O4: NATIONAL WEEK 1997 | AC4: NATIONAL WEEK 1993 | AQ4: NATIONAL WEEK 1982 | BE4: NATIONAL WEEK 1980 | BS4: NATIONAL WEEK 1974 | CG4: NATIONAL WEEK 1972
A5: N° | B5: DATE | C5: N1 | D5: N2 | E5: N3 | F5: N4 | G5: N5 | H5: TOT | I5: M1 | J5: M2 | K5: M3 | L5: M4 | M5: M5 | O5: N° | P5: DATE | Q5: N1 | R5: N2 | S5: N3 | T5: N4 | U5: N5 | V5: TOT | W5: M1 | X5: M2 | Y5: M3 | Z5: M4 | AA5: M5 | AC5: N° | AD5: DATE | AE5: N1 | AF5: N2 | AG5: N3 | AH5: N4 | AI5: N5 | AJ5: TOT | AK5: M1 | AL5: M2 | AM5: M3 | AN5: M4 | AO5: M5 | AQ5: N° | AR5: DATE | AS5: N1 | AT5: N2 | AU5: N3 | AV5: N4 | AW5: N5 | AX5: TOT | AY5: M1 | AZ5: M2 | BA5: M3 | BB5: M4 | BC5: M5 | BE5: N° | BF5: DATE | BG5: N1 | BH5: N2 | BI5: N3 | BJ5: N4 | BK5: N5 | BL5: TOT | BM5: M1 | BN5: M2 | BO5: M3 | BP5: M4 | BQ5: M5 | BS5: N° | BT5: DATE | BU5: N1 | BV5: N2 | BW5: N3 | BX5: N4 | BY5: N5 | BZ5: TOT | CA5: M1 | CB5: M2 | CC5: M3 | CD5: M4 | CE5: M5 | CG5: N° | CH5: DATE | CI5: N1 | CJ5: N2 | CK5: N3 | CL5: N4 | CM5: N5 | CN5: TOT | CO5: M1 | CP5: M2 | CQ5: M3 | CR5: M4 | CS5: M5
A6: 1995 | B6: 6/1 | C6: 51 | D6: 25 | E6: 77 | F6: 63 | G6: 73 | H6: =SUM(C6:G6) -> 289 | I6: 58 | J6: 29 | K6: 66 | L6: 13 | M6: 47 | O6: 1788 | P6: 4/1 | Q6: 82 | R6: 15 | S6: 32 | T6: 47 | U6: 79 | V6: =SUM(Q6:U6) -> 255 | W6: 57 | X6: 4 | Y6: 61 | Z6: 42 | AA6: 24 | AC6: 1579 | AD6: 2/1 | AE6: 86 | AF6: 36 | AG6: 24 | AH6: 48 | AI6: 37 | AJ6: =SUM(AE6:AI6) -> 231 | AK6: 58 | AL6: 9 | AM6: 90 | AN6: 35 | AO6: 3 | AQ6: 1005 | AR6: 2/1 | AS6: 66 | AT6: 33 | AU6: 83 | AV6: 52 | AW6: 8 | AX6: =SUM(AS6:AW6) -> 242 | AY6: 36 | AZ6: 64 | BA6: 73 | BB6: 87 | BC6: 32 | BE6: 901 | BF6: 5/1 | BG6: 6 | BH6: 9 | BI6: 59 | BJ6: 89 | BK6: 21 | BL6: =SUM(BG6:BK6) -> 184 | BM6: 56 | BN6: 43 | BO6: 3 | BP6: 46 | BQ6: 53 | BS6: 589 | BT6: 5/1 | BU6: 28 | BV6: 52 | BW6: 53 | BX6: 12 | BY6: 25 | BZ6: =SUM(BU6:BY6) -> 170 | CA6: 14 | CB6: 48 | CC6: 56 | CD6: 81 | CE6: 77 | CG6: 484 | CH6: 1/1 | CI6: 7 | CJ6: 86 | CK6: 18 | CL6: 71 | CM6: 21 | CN6: =SUM(CI6:CM6) -> 203 | CO6: 72 | CP6: 64 | CQ6: 32 | CR6: 37 | CS6: 88
A7: 1996 | B7: 13/1 | C7: 52 | D7: 65 | E7: 40 | F7: 14 | G7: 48 | H7: =SUM(C7:G7) -> 219 | I7: 23 | J7: 85 | K7: 19 | L7: 29 | M7: 68 | O7: 1789 | P7: 11/1 | Q7: 21 | R7: 3 | S7: 47 | T7: 39 | U7: 36 | V7: =SUM(Q7:U7) -> 146 | W7: 68 | X7: 74 | Y7: 89 | Z7: 67 | AA7: 49 | AC7: 1580 | AD7: 9/1 | AE7: 54 | AF7: 64 | AG7: 29 | AH7: 22 | AI7: 82 | AJ7: =SUM(AE7:AI7) -> 251 | AK7: 49 | AL7: 59 | AM7: 32 | AN7: 33 | AO7: 48 | AQ7: 1006 | AR7: 9/1 | AS7: 80 | AT7: 65 | AU7: 22 | AV7: 69 | AW7: 27 | AX7: =SUM(AS7:AW7) -> 263 | AY7: 26 | AZ7: 64 | BA7: 83 | BB7: 79 | BC7: 59 | BE7: 902 | BF7: 12/1 | BG7: 78 | BH7: 27 | BI7: 24 | BJ7: 28 | BK7: 37 | BL7: =SUM(BG7:BK7) -> 194 | BM7: 74 | BN7: 83 | BO7: 60 | BP7: 8 | BQ7: 63 | BS7: 590 | BT7: 12/1 | BU7: 58 | BV7: 37 | BW7: 49 | BX7: 3 | BY7: 60 | BZ7: =SUM(BU7:BY7) -> 207 | CA7: 85 | CB7: 62 | CC7: 28 | CD7: 69 | CE7: 33 | CG7: 485 | CH7: 8/1 | CI7: 27 | CJ7: 42 | CK7: 52 | CL7: 45 | CM7: 24 | CN7: =SUM(CI7:CM7) -> 190 | CO7: 57 | CP7: 71 | CQ7: 51 | CR7: 2 | CS7: 48
A8: 1997 | B8: 20/1 | C8: 26 | D8: 83 | E8: 87 | F8: 39 | G8: 3 | H8: =SUM(C8:G8) -> 238 | I8: 75 | J8: 36 | K8: 18 | L8: 89 | M8: 85 | O8: 1790 | P8: 18/1 | Q8: 71 | R8: 29 | S8: 83 | T8: 39 | U8: 36 | V8: =SUM(Q8:U8) -> 258 | W8: 79 | X8: 80 | Y8: 19 | Z8: 67 | AA8: 49 | AC8: 1581 | AD8: 16/1 | AE8: 18 | AF8: 36 | AG8: 26 | AH8: 71 | AI8: 13 | AJ8: =SUM(AE8:AI8) -> 164 | AK8: 65 | AL8: 6 | AM8: 49 | AN8: 63 | AO8: 40 | AQ8: 1007 | AR8: 16/1 | AS8: 65 | AT8: 74 | AU8: 23 | AV8: 27 | AW8: 12 | AX8: =SUM(AS8:AW8) -> 201 | AY8: 34 | AZ8: 45 | BA8: 46 | BB8: 75 | BC8: 56 | BE8: 903 | BF8: 19/1 | BG8: 11 | BH8: 78 | BI8: 48 | BJ8: 20 | BK8: 71 | BL8: =SUM(BG8:BK8) -> 228 | BM8: 51 | BN8: 6 | BO8: 56 | BP8: 16 | BQ8: 79 | BS8: 591 | BT8: 19/1 | BU8: 81 | BV8: 51 | BW8: 5 | BX8: 88 | BY8: 58 | BZ8: =SUM(BU8:BY8) -> 283 | CA8: 74 | CB8: 70 | CC8: 56 | CD8: 10 | CE8: 4 | CG8: 486 | CH8: 15/1 | CI8: 79 | CJ8: 73 | CK8: 52 | CL8: 35 | CM8: 17 | CN8: =SUM(CI8:CM8) -> 256 | CO8: 36 | CP8: 18 | CQ8: 9 | CR8: 47 | CS8: 10
A9: 1998 | B9: 27/1 | C9: 54 | D9: 52 | E9: 61 | F9: 8 | G9: 77 | H9: =SUM(C9:G9) -> 252 | I9: 43 | J9: 51 | K9: 15 | L9: 73 | M9: 44 | O9: 1791 | P9: 25/1 | Q9: 73 | R9: 16 | S9: 42 | T9: 55 | U9: 90 | V9: =SUM(Q9:U9) -> 276 | W9: 29 | X9: 17 | Y9: 60 | Z9: 7 | AA9: 38 | AC9: 1582 | AD9: 23/1 | AE9: 69 | AF9: 12 | AG9: 35 | AH9: 36 | AI9: 9 | AJ9: =SUM(AE9:AI9) -> 161 | AK9: 64 | AL9: 58 | AM9: 66 | AN9: 60 | AO9: 3 | AQ9: 1008 | AR9: 23/1 | AS9: 64 | AT9: 48 | AU9: 51 | AV9: 45 | AW9: 57 | AX9: =SUM(AS9:AW9) -> 265 | AY9: 28 | AZ9: 39 | BA9: 90 | BB9: 3 | BC9: 86 | BE9: 904 | BF9: 26/1 | BG9: 52 | BH9: 34 | BI9: 76 | BJ9: 19 | BK9: 5 | BL9: =SUM(BG9:BK9) -> 186 | BM9: 49 | BN9: 50 | BO9: 58 | BP9: 31 | BQ9: 55 | BS9: 592 | BT9: 26/1 | BU9: 70 | BV9: 37 | BW9: 11 | BX9: 19 | BY9: 73 | BZ9: =SUM(BU9:BY9) -> 210 | CA9: 49 | CB9: 48 | CC9: 55 | CD9: 58 | CE9: 22 | CG9: 487 | CH9: 22/1 | CI9: 57 | CJ9: 81 | CK9: 29 | CL9: 12 | CM9: 76 | CN9: =SUM(CI9:CM9) -> 255 | CO9: 53 | CP9: 58 | CQ9: 68 | CR9: 32 | CS9: 59
A10: 1999 | B10: 3/2 | C10: 35 | D10: 48 | E10: 54 | F10: 78 | G10: 56 | H10: =SUM(C10:G10) -> 271 | I10: 16 | J10: 55 | K10: 73 | L10: 29 | M10: 70 | O10: 1792 | P10: 1/2 | Q10: 16 | R10: 68 | S10: 19 | T10: 4 | U10: 36 | V10: =SUM(Q10:U10) -> 143 | W10: 15 | X10: 31 | Y10: 90 | Z10: 26 | AA10: 25 | AC10: 1583 | AD10: 30/1 | AE10: 57 | AF10: 82 | AG10: 81 | AH10: 26 | AI10: 32 | AJ10: =SUM(AE10:AI10) -> 278 | AK10: 21 | AL10: 5 | AM10: 37 | AN10: 17 | AO10: 28 | AQ10: 1009 | AR10: 30/1 | AS10: 50 | AT10: 79 | AU10: 76 | AV10: 53 | AW10: 86 | AX10: =SUM(AS10:AW10) -> 344 | AY10: 31 | AZ10: 8 | BA10: 23 | BB10: 58 | BC10: 2 | BE10: 905 | BF10: 2/2 | BG10: 28 | BH10: 11 | BI10: 22 | BJ10: 39 | BK10: 24 | BL10: =SUM(BG10:BK10) -> 124 | BM10: 78 | BN10: 67 | BO10: 60 | BP10: 9 | BQ10: 27 | BS10: 593 | BT10: 2/2 | BU10: 22 | BV10: 90 | BW10: 81 | BX10: 82 | BY10: 49 | BZ10: =SUM(BU10:BY10) -> 324 | CA10: 1 | CB10: 57 | CC10: 88 | CD10: 23 | CE10: 47 | CG10: 488 | CH10: 29/1 | CI10: 74 | CJ10: 15 | CK10: 71 | CL10: 45 | CM10: 53 | CN10: =SUM(CI10:CM10) -> 258 | CO10: 43 | CP10: 23 | CQ10: 31 | CR10: 25 | CS10: 18
A11: 2000 | B11: 10/2 | C11: 88 | D11: 22 | E11: 61 | F11: 64 | G11: 50 | H11: =SUM(C11:G11) -> 285 | I11: 3 | J11: 15 | K11: 8 | L11: 27 | M11: 70 | O11: 1793 | P11: 8/2 | Q11: 69 | R11: 30 | S11: 75 | T11: 65 | U11: 12 | V11: =SUM(Q11:U11) -> 251 | W11: 19 | X11: 21 | Y11: 61 | Z11: 80 | AA11: 57 | AC11: 1584 | AD11: 6/2 | AE11: 13 | AF11: 11 | AG11: 60 | AH11: 52 | AI11: 63 | AJ11: =SUM(AE11:AI11) -> 199 | AK11: 10 | AL11: 49 | AM11: 68 | AN11: 77 | AO11: 82 | AQ11: 1010 | AR11: 6/2 | AS11: 30 | AT11: 85 | AU11: 63 | AV11: 49 | AW11: 57 | AX11: =SUM(AS11:AW11) -> 284 | AY11: 73 | AZ11: 9 | BA11: 28 | BB11: 24 | BC11: 36 | BE11: 906 | BF11: 9/2 | BG11: 61 | BH11: 63 | BI11: 45 | BJ11: 19 | BK11: 18 | BL11: =SUM(BG11:BK11) -> 206 | BM11: 28 | BN11: 37 | BO11: 20 | BP11: 54 | BQ11: 24 | BS11: 594 | BT11: 9/2 | BU11: 74 | BV11: 13 | BW11: 47 | BX11: 2 | BY11: 10 | BZ11: =SUM(BU11:BY11) -> 146 | CA11: 61 | CB11: 18 | CC11: 26 | CD11: 67 | CE11: 79 | CG11: 489 | CH11: 5/2 | CI11: 74 | CJ11: 51 | CK11: 54 | CL11: 77 | CM11: 47 | CN11: =SUM(CI11:CM11) -> 303 | CO11: 64 | CP11: 39 | CQ11: 66 | CR11: 72 | CS11: 35
A12: 2001 | B12: 17/2 | C12: 74 | D12: 50 | E12: 67 | F12: 25 | G12: 56 | H12: =SUM(C12:G12) -> 272 | I12: 44 | J12: 76 | K12: 60 | L12: 2 | M12: 51 | O12: 1794 | P12: 15/2 | Q12: 65 | R12: 21 | S12: 71 | T12: 8 | U12: 46 | V12: =SUM(Q12:U12) -> 211 | W12: 15 | X12: 74 | Y12: 81 | Z12: 43 | AA12: 55 | AC12: 1585 | AD12: 13/2 | AE12: 5 | AF12: 17 | AG12: 77 | AH12: 84 | AI12: 42 | AJ12: =SUM(AE12:AI12) -> 225 | AK12: 16 | AL12: 76 | AM12: 35 | AN12: 48 | AO12: 63 | AQ12: 1011 | AR12: 13/2 | AS12: 45 | AT12: 17 | AU12: 75 | AV12: 50 | AW12: 41 | AX12: =SUM(AS12:AW12) -> 228 | AY12: 34 | AZ12: 13 | BA12: 77 | BB12: 23 | BC12: 74 | BE12: 907 | BF12: 16/2 | BG12: 89 | BH12: 16 | BI12: 83 | BJ12: 50 | BK12: 69 | BL12: =SUM(BG12:BK12) -> 307 | BM12: 1 | BN12: 3 | BO12: 32 | BP12: 57 | BQ12: 67 | BS12: 595 | BT12: 16/2 | BU12: 22 | BV12: 38 | BW12: 46 | BX12: 21 | BY12: 57 | BZ12: =SUM(BU12:BY12) -> 184 | CA12: 66 | CB12: 76 | CC12: 16 | CD12: 37 | CE12: 79 | CG12: 490 | CH12: 12/2 | CI12: 12 | CJ12: 44 | CK12: 54 | CL12: 28 | CM12: 8 | CN12: =SUM(CI12:CM12) -> 146 | CO12: 3 | CP12: 42 | CQ12: 19 | CR12: 65 | CS12: 4
A13: 2002 | B13: 24/2 | C13: 14 | D13: 73 | E13: 65 | F13: 89 | G13: 87 | H13: =SUM(C13:G13) -> 328 | I13: 9 | J13: 11 | K13: 55 | L13: 57 | M13: 77 | O13: 1795 | P13: 22/2 | Q13: 22 | R13: 86 | S13: 7 | T13: 55 | U13: 18 | V13: =SUM(Q13:U13) -> 188 | W13: 42 | X13: 77 | Y13: 36 | Z13: 56 | AA13: 41 | AC13: 1586 | AD13: 20/2 | AE13: 2 | AF13: 8 | AG13: 77 | AH13: 46 | AI13: 72 | AJ13: =SUM(AE13:AI13) -> 205 | AK13: 35 | AL13: 90 | AM13: 44 | AN13: 27 | AO13: 12 | AQ13: 1012 | AR13: 20/2 | AS13: 61 | AT13: 3 | AU13: 74 | AV13: 68 | AW13: 40 | AX13: =SUM(AS13:AW13) -> 246 | AY13: 55 | AZ13: 17 | BA13: 24 | BB13: 72 | BC13: 80 | BE13: 908 | BF13: 23/2 | BG13: 50 | BH13: 13 | BI13: 2 | BJ13: 90 | BK13: 24 | BL13: =SUM(BG13:BK13) -> 179 | BM13: 29 | BN13: 49 | BO13: 28 | BP13: 66 | BQ13: 74 | BS13: 596 | BT13: 23/2 | BU13: 7 | BV13: 81 | BW13: 76 | BX13: 12 | BY13: 47 | BZ13: =SUM(BU13:BY13) -> 223 | CA13: 55 | CB13: 29 | CC13: 25 | CD13: 60 | CE13: 24 | CG13: 491 | CH13: 19/2 | CI13: 53 | CJ13: 56 | CK13: 49 | CL13: 42 | CM13: 11 | CN13: =SUM(CI13:CM13) -> 211 | CO13: 88 | CP13: 45 | CQ13: 14 | CR13: 2 | CS13: 55
A14: 2003 | B14: 3/3 | C14: 36 | D14: 13 | E14: 7 | F14: 75 | G14: 9 | H14: =SUM(C14:G14) -> 140 | I14: 53 | J14: 32 | K14: 10 | L14: 26 | M14: 42 | O14: 1796 | P14: 1/3 | Q14: 45 | R14: 57 | S14: 62 | T14: 42 | U14: 56 | V14: =SUM(Q14:U14) -> 262 | W14: 46 | X14: 87 | Y14: 29 | Z14: 14 | AA14: 16 | AC14: 1587 | AD14: 27/2 | AE14: 10 | AF14: 58 | AG14: 43 | AH14: 14 | AI14: 79 | AJ14: =SUM(AE14:AI14) -> 204 | AK14: 56 | AL14: 77 | AM14: 25 | AN14: 40 | AO14: 73 | AQ14: 1013 | AR14: 27/2 | AS14: 16 | AT14: 58 | AU14: 57 | AV14: 18 | AW14: 38 | AX14: =SUM(AS14:AW14) -> 187 | AY14: 79 | AZ14: 90 | BA14: 87 | BB14: 24 | BC14: 80 | BE14: 909 | BF14: 1/3 | BG14: 44 | BH14: 9 | BI14: 12 | BJ14: 74 | BK14: 24 | BL14: =SUM(BG14:BK14) -> 163 | BM14: 31 | BN14: 83 | BO14: 26 | BP14: 68 | BQ14: 78 | BS14: 597 | BT14: 2/3 | BU14: 81 | BV14: 44 | BW14: 12 | BX14: 42 | BY14: 25 | BZ14: =SUM(BU14:BY14) -> 204 | CA14: 46 | CB14: 57 | CC14: 75 | CD14: 19 | CE14: 60 | CG14: 492 | CH14: 26/2 | CI14: 17 | CJ14: 6 | CK14: 72 | CL14: 52 | CM14: 1 | CN14: =SUM(CI14:CM14) -> 148 | CO14: 90 | CP14: 14 | CQ14: 32 | CR14: 82 | CS14: 39
A15: 2004 | B15: 10/3 | C15: 54 | D15: 60 | E15: 14 | F15: 49 | G15: 37 | H15: =SUM(C15:G15) -> 214 | I15: 61 | J15: 78 | K15: 45 | L15: 41 | M15: 52 | O15: 1797 | P15: 8/3 | Q15: 5 | R15: 54 | S15: 48 | T15: 56 | U15: 3 | V15: =SUM(Q15:U15) -> 166 | W15: 59 | X15: 85 | Y15: 4 | Z15: 6 | AA15: 40 | AC15: 1588 | AD15: 6/3 | AE15: 75 | AF15: 55 | AG15: 83 | AH15: 53 | AI15: 3 | AJ15: =SUM(AE15:AI15) -> 269 | AK15: 2 | AL15: 86 | AM15: 43 | AN15: 61 | AO15: 56 | AQ15: 1014 | AR15: 6/3 | AS15: 70 | AT15: 53 | AU15: 2 | AV15: 52 | AW15: 11 | AX15: =SUM(AS15:AW15) -> 188 | AY15: 71 | AZ15: 30 | BA15: 50 | BB15: 68 | BC15: 14 | BE15: 910 | BF15: 8/3 | BG15: 52 | BH15: 26 | BI15: 72 | BJ15: 69 | BK15: 39 | BL15: =SUM(BG15:BK15) -> 258 | BM15: 49 | BN15: 48 | BO15: 1 | BP15: 57 | BQ15: 38 | BS15: 598 | BT15: 9/3 | BU15: 35 | BV15: 46 | BW15: 28 | BX15: 41 | BY15: 64 | BZ15: =SUM(BU15:BY15) -> 214 | CA15: 75 | CB15: 36 | CC15: 73 | CD15: 66 | CE15: 49 | CG15: 493 | CH15: 4/3 | CI15: 21 | CJ15: 87 | CK15: 56 | CL15: 42 | CM15: 3 | CN15: =SUM(CI15:CM15) -> 209 | CO15: 67 | CP15: 48 | CQ15: 34 | CR15: 57 | CS15: 58
A16: 2005 | B16: 17/3 | C16: 55 | D16: 21 | E16: 76 | F16: 69 | G16: 57 | H16: =SUM(C16:G16) -> 278 | I16: 35 | J16: 60 | K16: 81 | L16: 4 | M16: 74 | O16: 1798 | P16: 15/3 | Q16: 1 | R16: 13 | S16: 66 | T16: 78 | U16: 26 | V16: =SUM(Q16:U16) -> 184 | W16: 43 | X16: 27 | Y16: 8 | Z16: 21 | AA16: 6 | AC16: 1589 | AD16: 13/3 | AE16: 76 | AF16: 84 | AG16: 33 | AH16: 49 | AI16: 20 | AJ16: =SUM(AE16:AI16) -> 262 | AK16: 11 | AL16: 17 | AM16: 80 | AN16: 22 | AO16: 37 | AQ16: 1015 | AR16: 13/3 | AS16: 5 | AT16: 46 | AU16: 74 | AV16: 71 | AW16: 12 | AX16: =SUM(AS16:AW16) -> 208 | AY16: 47 | AZ16: 30 | BA16: 22 | BB16: 55 | BC16: 41 | BE16: 911 | BF16: 15/3 | BG16: 52 | BH16: 35 | BI16: 89 | BJ16: 15 | BK16: 10 | BL16: =SUM(BG16:BK16) -> 201 | BM16: 63 | BN16: 37 | BO16: 62 | BP16: 55 | BQ16: 54 | BS16: 599 | BT16: 16/3 | BU16: 32 | BV16: 54 | BW16: 19 | BX16: 50 | BY16: 21 | BZ16: =SUM(BU16:BY16) -> 176 | CA16: 87 | CB16: 18 | CC16: 11 | CD16: 31 | CE16: 57 | CG16: 494 | CH16: 11/3 | CI16: 41 | CJ16: 7 | CK16: 29 | CL16: 43 | CM16: 85 | CN16: =SUM(CI16:CM16) -> 205 | CO16: 30 | CP16: 37 | CQ16: 56 | CR16: 4 | CS16: 5
A17: 2006 | B17: 24/3 | C17: 85 | D17: 35 | E17: 30 | F17: 76 | G17: 7 | H17: =SUM(C17:G17) -> 233 | I17: 90 | J17: 63 | K17: 61 | L17: 71 | M17: 77 | O17: 1799 | P17: 22/3 | Q17: 20 | R17: 16 | S17: 76 | T17: 37 | U17: 69 | V17: =SUM(Q17:U17) -> 218 | W17: 12 | X17: 41 | Y17: 57 | Z17: 27 | AA17: 86 | AC17: 1590 | AD17: 20/3 | AE17: 67 | AF17: 43 | AG17: 2 | AH17: 23 | AI17: 55 | AJ17: =SUM(AE17:AI17) -> 190 | AK17: 26 | AL17: 42 | AM17: 83 | AN17: 20 | AO17: 84 | AQ17: 1016 | AR17: 20/3 | AS17: 82 | AT17: 33 | AU17: 84 | AV17: 57 | AW17: 54 | AX17: =SUM(AS17:AW17) -> 310 | AY17: 66 | AZ17: 53 | BA17: 40 | BB17: 59 | BC17: 77 | BE17: 912 | BF17: 22/3 | BG17: 5 | BH17: 28 | BI17: 31 | BJ17: 50 | BK17: 54 | BL17: =SUM(BG17:BK17) -> 168 | BM17: 51 | BN17: 30 | BO17: 66 | BP17: 53 | BQ17: 32 | BS17: 600 | BT17: 23/3 | BU17: 46 | BV17: 10 | BW17: 29 | BX17: 55 | BY17: 77 | BZ17: =SUM(BU17:BY17) -> 217 | CA17: 59 | CB17: 28 | CC17: 42 | CD17: 62 | CE17: 4 | CG17: 495 | CH17: 18/3 | CI17: 20 | CJ17: 11 | CK17: 41 | CL17: 64 | CM17: 2 | CN17: =SUM(CI17:CM17) -> 138 | CO17: 74 | CP17: 45 | CQ17: 38 | CR17: 15 | CS17: 55
... A57: 2046 | B57: 29/12 | C57: 35 | D57: 3 | E57: 16 | F57: 21 | G57: 41 | H57: =SUM(C57:G57) -> 116 | I57: 75 | J57: 60 | K57: 45 | L57: 53 | M57: 82 | O57: 1839 | P57: 27/12 | Q57: 8 | R57: 67 | S57: 77 | T57: 57 | U57: 25 | V57: =SUM(Q57:U57) -> 234 | W57: 60 | X57: 89 | Y57: 18 | Z57: 55 | AA57: 62 | AC57: 1630 | AD57: 25/12 | AE57: 60 | AF57: 45 | AG57: 53 | AH57: 40 | AI57: 87 | AJ57: =SUM(AE57:AI57) -> 285 | AK57: 28 | AL57: 74 | AM57: 39 | AN57: 10 | AO57: 85 | AQ57: 1056 | AR57: 25/12 | AS57: 77 | AT57: 43 | AU57: 37 | AV57: 59 | AW57: 7 | AX57: =SUM(AS57:AW57) -> 223 | AY57: 15 | AZ57: 83 | BA57: 12 | BB57: 48 | BC57: 35 | BE57: 952 | BF57: 27/12 | BG57: 56 | BH57: 88 | BI57: 17 | BJ57: 75 | BK57: 35 | BL57: =SUM(BG57:BK57) -> 271 | BM57: 13 | BN57: 54 | BO57: 4 | BP57: 42 | BQ57: 48 | BS57: 640 | BT57: 28/12 | BU57: 1 | BV57: 41 | BW57: 58 | BX57: 18 | BY57: 30 | BZ57: =SUM(BU57:BY57) -> 148 | CA57: 71 | CB57: 80 | CC57: 11 | CD57: 79 | CE57: 84 | CG57: 535 | CH57: 23/12 | CI57: 85 | CJ57: 74 | CK57: 65 | CL57: 33 | CM57: 54 | CN57: =SUM(CI57:CM57) -> 311 | CO57: 34 | CP57: 8 | CQ57: 67 | CR57: 66 | CS57: 68
CG58: 536 | CH58: 30/12 | CI58: 9 | CJ58: 1 | CK58: 42 | CL58: 88 | CM58: 89 | CN58: =SUM(CI58:CM58) -> 229 | CO58: 66 | CP58: 83 | CQ58: 53 | CR58: 80 | CS58: 78

Sheet BINGO 2024
A1: BINGO 2024
A2: N° | B2: Date | C2: N1 | D2: N2 | E2: N3 | F2: N4 | G2: N5 | H2: TOTAL
A3: BINGO028 | B3: 6/1/2024 | C3: 46 | D3: 34 | E3: 50 | F3: 40 | G3: 51 | H3: =SUM(C3:G3) -> 221
A4: BINGO029 | B4: 13/1/2024 | C4: 86 | D4: 45 | E4: 35 | F4: 22 | G4: 26 | H4: =SUM(C4:G4) -> 214
A5: BINGO030 | B5: 20/1/2024 | C5: 79 | D5: 82 | E5: 6 | F5: 68 | G5: 64 | H5: =SUM(C5:G5) -> 299
A6: BINGO031 | B6: 27/1/2024 | C6: 26 | D6: 12 | E6: 49 | F6: 55 | G6: 42 | H6: =SUM(C6:G6) -> 184
A7: BINGO032 | B7: 3/2/2024 | C7: 2 | D7: 85 | E7: 82 | F7: 42 | G7: 55 | H7: =SUM(C7:G7) -> 266
A8: BINGO033 | B8: 10/2/2024 | C8: 3 | D8: 47 | E8: 2 | F8: 43 | G8: 46 | H8: =SUM(C8:G8) -> 141
A9: BINGO034 | B9: 17/2/2024 | C9: 40 | D9: 23 | E9: 41 | F9: 81 | G9: 39 | H9: =SUM(C9:G9) -> 224
A10: BINGO035 | B10: 24/2/2024 | C10: 70 | D10: 51 | E10: 32 | F10: 53 | G10: 9 | H10: =SUM(C10:G10) -> 215
A11: BINGO036 | B11: 2/3/2024 | C11: 22 | D11: 24 | E11: 37 | F11: 36 | G11: 33 | H11: =SUM(C11:G11) -> 152
A12: BINGO037 | B12: 9/3/2024 | C12: 87 | D12: 35 | E12: 29 | F12: 21 | G12: 13 | H12: =SUM(C12:G12) -> 185
A13: BINGO038 | B13: 16/3/2024 | C13: 19 | D13: 7 | E13: 3 | F13: 83 | G13: 87 | H13: =SUM(C13:G13) -> 199
A14: BINGO039 | B14: 23/3/2024 | C14: 6 | D14: 55 | E14: 83 | F14: 10 | G14: 51 | H14: =SUM(C14:G14) -> 205
... A54: BINGO079 | B54: 28/12/2024 | C54: 29 | D54: 38 | E54: 57 | F54: 90 | G54: 31 | H54: =SUM(C54:G54) -> 245
A57: Statistiques 2024
A58: Nombre de tirages
A59: Total général
A60: Moyenne TOTAL
A61: TOTAL max
A62: TOTAL min
A63: Moyenne N1
A64: Moyenne N2
A65: Moyenne N3
A66: Moyenne N4
A67: Moyenne N5

Sheet BINGO 2023
A1: BINGO 2023
A2: N° | B2: Date | C2: N1 | D2: N2 | E2: N3 | F2: N4 | G2: N5 | H2: TOTAL
A3: BINGO001 | B3: 1/7/2023 | C3: 67 | D3: 6 | E3: 90 | F3: 72 | G3: 47 | H3: =SUM(C3:G3) -> 282
A4: BINGO002 | B4: 8/7/2023 | C4: 82 | D4: 55 | E4: 31 | F4: 34 | G4: 86 | H4: =SUM(C4:G4) -> 288
A5: BINGO003 | B5: 15/7/2023 | C5: 28 | D5: 37 | E5: 58 | F5: 64 | G5: 52 | H5: =SUM(C5:G5) -> 239
A6: BINGO004 | B6: 22/7/2023 | C6: 31 | D6: 52 | E6: 77 | F6: 13 | G6: 33 | H6: =SUM(C6:G6) -> 206
A7: BINGO005 | B7: 29/7/2023 | C7: 33 | D7: 4 | E7: 12 | F7: 22 | G7: 58 | H7: =SUM(C7:G7) -> 129
A8: BINGO006 | B8: 5/8/2023 | C8: 63 | D8: 1 | E8: 35 | F8: 86 | G8: 55 | H8: =SUM(C8:G8) -> 240
A9: BINGO007 | B9: 12/8/2023 | C9: 2 | D9: 76 | E9: 9 | F9: 22 | G9: 48 | H9: =SUM(C9:G9) -> 157
A10: BINGO008 | B10: 19/8/2023 | C10: 27 | D10: 89 | E10: 59 | F10: 49 | G10: 46 | H10: =SUM(C10:G10) -> 270
A11: BINGO009 | B11: 26/8/2023 | C11: 15 | D11: 87 | E11: 23 | F11: 14 | G11: 74 | H11: =SUM(C11:G11) -> 213
A12: BINGO010 | B12: 2/9/2023 | C12: 7 | D12: 69 | E12: 20 | F12: 25 | G12: 66 | H12: =SUM(C12:G12) -> 187
A13: BINGO011 | B13: 9/9/2023 | C13: 9 | D13: 35 | E13: 45 | F13: 32 | G13: 52 | H13: =SUM(C13:G13) -> 173
A14: BINGO012 | B14: 16/9/2023 | C14: 88 | D14: 14 | E14: 9 | F14: 70 | G14: 21 | H14: =SUM(C14:G14) -> 202
... A29: BINGO027 | B29: 30/12/2023 | C29: 46 | D29: 26 | E29: 8 | F29: 38 | G29: 25 | H29: =SUM(C29:G29) -> 143
A32: Statistiques 2023
A33: Nombre de tirages
A34: Total général
A35: Moyenne TOTAL
A36: TOTAL max
A37: TOTAL min
A38: Moyenne N1
A39: Moyenne N2
A40: Moyenne N3
A41: Moyenne N4
A42: Moyenne N5

Sheet STATISTIQUES GLOBAL
A1: STATISTIQUES GLOBALES
A3: Année | B3: Tirages | C3: Total | D3: Moyenne | E3: Max | F3: Min
A4: 2026 | B4: =COUNTA('BINGO 2026'!A3:A29) -> 27 | C4: =SUM('BINGO 2026'!H3:H29) -> 5633 | D4: =AVERAGE('BINGO 2026'!H3:H29) -> 208.62963 | E4: =MAX('BINGO 2026'!H3:H29) -> 276 | F4: =MIN('BINGO 2026'!H3:H29) -> 76
A5: 2025 | B5: =COUNTA('BINGO 2025'!A3:A54) -> 52 | C5: =SUM('BINGO 2025'!H3:H54) -> 12296 | D5: =AVERAGE('BINGO 2025'!H3:H54) -> 236.46154 | E5: =MAX('BINGO 2025'!H3:H54) -> 344 | F5: =MIN('BINGO 2025'!H3:H54) -> 109
A6: 2024 | B6: =COUNTA('BINGO 2024'!A3:A54) -> 52 | C6: =SUM('BINGO 2024'!H3:H54) -> 11655 | D6: =AVERAGE('BINGO 2024'!H3:H54) -> 224.13462 | E6: =MAX('BINGO 2024'!H3:H54) -> 349 | F6: =MIN('BINGO 2024'!H3:H54) -> 131
A7: 2023 | B7: =COUNTA('BINGO 2023'!A3:A29) -> 27 | C7: =SUM('BINGO 2023'!H3:H29) -> 6103 | D7: =AVERAGE('BINGO 2023'!H3:H29) -> 226.03704 | E7: =MAX('BINGO 2023'!H3:H29) -> 331 | F7: =MIN('BINGO 2023'!H3:H29) -> 129
A8: TOTAL | B8: =SUM(B4:B7) -> 158 | C8: =SUM(C4:C7) -> 35687 | D8: =AVERAGE(D4:D7) -> 223.81571 | E8: =MAX(E4:E7) -> 349 | F8: =MIN(F4:F7) -> 76
A11: FRÉQUENCE DES NUMÉROS (toutes années)
A12: Numéro | B12: Sorties | D12: Numéro | E12: Sorties
A13: 1 | B13: 11 | D13: 46 | E13: 15
A14: 2 | B14: 7 | D14: 47 | E14: 9
A15: 3 | B15: 8 | D15: 48 | E15: 8
A16: 4 | B16: 9 | D16: 49 | E16: 8
A17: 5 | B17: 8 | D17: 50 | E17: 8
A18: 6 | B18: 10 | D18: 51 | E18: 10
A19: 7 | B19: 12 | D19: 52 | E19: 11
A20: 8 | B20: 7 | D20: 53 | E20: 7
A21: 9 | B21: 11 | D21: 54 | E21: 11
A22: 10 | B22: 6 | D22: 55 | E22: 11
A23: 11 | B23: 9 | D23: 56 | E23: 7
A24: 12 | B24: 8 | D24: 57 | E24: 5
... A57: 45 | B57: 14 | D57: 90 | E57: 7
A60: TOP 10 (les + sortis) | D60: FLOP 10 (les - sortis)
A61: 46 | B61: 15 | D61: 85 | E61: 3
A62: 24 | B62: 14 | D62: 75 | E62: 4
A63: 45 | B63: 14 | D63: 78 | E63: 4
A64: 35 | B64: 14 | D64: 15 | E64: 5
A65: 13 | B65: 13 | D65: 16 | E65: 5
A66: 86 | B66: 13 | D66: 19 | E66: 5
A67: 31 | B67: 13 | D67: 30 | E67: 5
A68: 81 | B68: 13 | D68: 39 | E68: 5
A69: 34 | B69: 13 | D69: 57 | E69: 5
A70: 7 | B70: 12 | D70: 74 | E70: 5

Sheet Feuil1
A1: NATIONAL WEEK 1962 | J1: NATIONAL WEEK 1963 | S1: NATIONAL WEEK 1964 | AB1: NATIONAL WEEK 1965 | AK1: NATIONAL WEEK 1966 | AT1: NATIONAL WEEK 1967 | BC1: NATIONAL WEEK 1968 | BL1: NATIONAL WEEK 1969 | BU1: NATIONAL WEEK 1970 | CD1: NATIONAL WEEK 1971 | CM1: NATIONAL WEEK 1972 | CV1: NATIONAL WEEK 1973 | DE1: NATIONAL WEEK 1974 (en cours)
A2: TIRAGE | B2: DATE | C2: N°1 | D2: N°2 | E2: N°3 | F2: N°4 | G2: N°5 | H2: TOTAL | J2: TIRAGE | K2: DATE | L2: N°1 | M2: N°2 | N2: N°3 | O2: N°4 | P2: N°5 | Q2: TOTAL | S2: TIRAGE | T2: DATE | U2: N°1 | V2: N°2 | W2: N°3 | X2: N°4 | Y2: N°5 | Z2: TOTAL | AB2: TIRAGE | AC2: DATE | AD2: N°1 | AE2: N°2 | AF2: N°3 | AG2: N°4 | AH2: N°5 | AI2: TOTAL | AK2: TIRAGE | AL2: DATE | AM2: N°1 | AN2: N°2 | AO2: N°3 | AP2: N°4 | AQ2: N°5 | AR2: TOTAL | AT2: TIRAGE | AU2: DATE | AV2: N°1 | AW2: N°2 | AX2: N°3 | AY2: N°4 | AZ2: N°5 | BA2: TOTAL | BC2: TIRAGE | BD2: DATE | BE2: N°1 | BF2: N°2 | BG2: N°3 | BH2: N°4 | BI2: N°5 | BJ2: TOTAL | BL2: TIRAGE | BM2: DATE | BN2: N°1 | BO2: N°2 | BP2: N°3 | BQ2: N°4 | BR2: N°5 | BS2: TOTAL | BU2: TIRAGE | BV2: DATE | BW2: N°1 | BX2: N°2 | BY2: N°3 | BZ2: N°4 | CA2: N°5 | CB2: TOTAL | CD2: TIRAGE | CE2: DATE | CF2: N°1 | CG2: N°2 | CH2: N°3 | CI2: N°4 | CJ2: N°5 | CK2: TOTAL | CM2: TIRAGE | CN2: DATE | CO2: N°1 | CP2: N°2 | CQ2: N°3 | CR2: N°4 | CS2: N°5 | CT2: TOTAL | CV2: TIRAGE | CW2: DATE | CX2: N°1 | CY2: N°2 | CZ2: N°3 | DA2: N°4 | DB2: N°5 | DC2: TOTAL | DE2: TIRAGE | DF2: DATE | DG2: N°1 | DH2: N°2 | DI2: N°3 | DJ2: N°4 | DK2: N°5 | DL2: TOTAL
A3: 1 | B3: 29/9 | C3: 41 | D3: 89 | E3: 80 | F3: 62 | G3: 45 | H3: =C3+D3+E3+F3+G3 -> 317 | J3: 15 | K3: 5/1 | L3: 41 | M3: 48 | N3: 45 | O3: 70 | P3: 31 | Q3: =L3+M3+N3+O3+P3 -> 235 | S3: 67 | T3: 4/1 | U3: 65 | V3: 8 | W3: 56 | X3: 39 | Y3: 90 | Z3: =U3+V3+W3+X3+Y3 -> 258 | AB3: 119 | AC3: 2/1 | AD3: 80 | AE3: 47 | AF3: 22 | AG3: 69 | AH3: 82 | AI3: =AD3+AE3+AF3+AG3+AH3 -> 300 | AK3: 171 | AL3: 1/1 | AM3: 21 | AN3: 84 | AO3: 85 | AP3: 20 | AQ3: 24 | AR3: =AM3+AN3+AO3+AP3+AQ3 -> 234 | AT3: 224 | AU3: 7/1 | AV3: 64 | AW3: 28 | AX3: 30 | AY3: 71 | AZ3: 4 | BA3: =AV3+AW3+AX3+AY3+AZ3 -> 197 | BC3: 276 | BD3: 6/1 | BE3: 72 | BF3: 75 | BG3: 70 | BH3: 10 | BI3: 53 | BJ3: =BE3+BF3+BG3+BH3+BI3 -> 280 | BL3: 328 | BM3: 4/1 | BN3: 25 | BO3: 8 | BP3: 19 | BQ3: 53 | BR3: 73 | BS3: =BN3+BO3+BP3+BQ3+BR3 -> 178 | BU3: 380 | BV3: 3/1 | BW3: 85 | BX3: 59 | BY3: 37 | BZ3: 65 | CA3: 89 | CB3: =BW3+BX3+BY3+BZ3+CA3 -> 335 | CD3: 432 | CE3: 2/1 | CF3: 67 | CG3: 63 | CH3: 14 | CI3: 75 | CJ3: 17 | CK3: =CF3+CG3+CH3+CI3+CJ3 -> 236 | CM3: 484 | CN3: 1/1 | CO3: 7 | CP3: 86 | CQ3: 18 | CR3: 71 | CS3: 21 | CT3: =CO3+CP3+CQ3+CR3+CS3 -> 203 | CV3: 537 | CW3: 6/1 | CX3: 11 | CY3: 90 | CZ3: 22 | DA3: 8 | DB3: 62 | DC3: =CX3+CY3+CZ3+DA3+DB3 -> 193 | DE3: 589 | DF3: 5/1 | DG3: 28 | DH3: 52 | DI3: 53 | DJ3: 12 | DK3: 25 | DL3: =DG3+DH3+DI3+DJ3+DK3 -> 170
A4: 2 | B4: 6/10 | C4: 79 | D4: 88 | E4: 25 | F4: 26 | G4: 47 | H4: =C4+D4+E4+F4+G4 -> 265 | J4: 16 | K4: 12/1 | L4: 9 | M4: 55 | N4: 43 | O4: 80 | P4: 33 | Q4: =L4+M4+N4+O4+P4 -> 220 | S4: 68 | T4: 11/1 | U4: 78 | V4: 80 | W4: 46 | X4: 9 | Y4: 41 | Z4: =U4+V4+W4+X4+Y4 -> 254 | AB4: 120 | AC4: 9/1 | AD4: 41 | AE4: 16 | AF4: 86 | AG4: 21 | AH4: 82 | AI4: =AD4+AE4+AF4+AG4+AH4 -> 246 | AK4: 172 | AL4: 8/1 | AM4: 73 | AN4: 52 | AO4: 54 | AP4: 30 | AQ4: 70 | AR4: =AM4+AN4+AO4+AP4+AQ4 -> 279 | AT4: 225 | AU4: 14/1 | AV4: 50 | AW4: 73 | AX4: 59 | AY4: 76 | AZ4: 13 | BA4: =AV4+AW4+AX4+AY4+AZ4 -> 271 | BC4: 277 | BD4: 13/1 | BE4: 86 | BF4: 23 | BG4: 28 | BH4: 6 | BI4: 14 | BJ4: =BE4+BF4+BG4+BH4+BI4 -> 157 | BL4: 329 | BM4: 11/1 | BN4: 35 | BO4: 2 | BP4: 27 | BQ4: 51 | BR4: 82 | BS4: =BN4+BO4+BP4+BQ4+BR4 -> 197 | BU4: 381 | BV4: 10/1 | BW4: 46 | BX4: 1 | BY4: 7 | BZ4: 79 | CA4: 24 | CB4: =BW4+BX4+BY4+BZ4+CA4 -> 157 | CD4: 433 | CE4: 9/1 | CF4: 8 | CG4: 19 | CH4: 52 | CI4: 10 | CJ4: 83 | CK4: =CF4+CG4+CH4+CI4+CJ4 -> 172 | CM4: 485 | CN4: 8/1 | CO4: 27 | CP4: 42 | CQ4: 52 | CR4: 45 | CS4: 24 | CT4: =CO4+CP4+CQ4+CR4+CS4 -> 190 | CV4: 538 | CW4: 13/1 | CX4: 60 | CY4: 4 | CZ4: 67 | DA4: 71 | DB4: 19 | DC4: =CX4+CY4+CZ4+DA4+DB4 -> 221 | DE4: 590 | DF4: 12/1 | DG4: 58 | DH4: 37 | DI4: 49 | DJ4: 3 | DK4: 60 | DL4: =DG4+DH4+DI4+DJ4+DK4 -> 207
A5: 3 | B5: 13/10 | C5: 19 | D5: 86 | E5: 62 | F5: 46 | G5: 48 | H5: =C5+D5+E5+F5+G5 -> 261 | J5: 17 | K5: 19/1 | L5: 62 | M5: 28 | N5: 10 | O5: 52 | P5: 85 | Q5: =L5+M5+N5+O5+P5 -> 237 | S5: 69 | T5: 18/1 | U5: 48 | V5: 15 | W5: 1 | X5: 16 | Y5: 44 | Z5: =U5+V5+W5+X5+Y5 -> 124 | AB5: 121 | AC5: 16/1 | AD5: 58 | AE5: 54 | AF5: 25 | AG5: 80 | AH5: 35 | AI5: =AD5+AE5+AF5+AG5+AH5 -> 252 | AK5: 173 | AL5: 15/1 | AM5: 10 | AN5: 78 | AO5: 81 | AP5: 71 | AQ5: 14 | AR5: =AM5+AN5+AO5+AP5+AQ5 -> 254 | AT5: 226 | AU5: 21/1 | AV5: 15 | AW5: 71 | AX5: 21 | AY5: 80 | AZ5: 59 | BA5: =AV5+AW5+AX5+AY5+AZ5 -> 246 | BC5: 278 | BD5: 20/1 | BE5: 5 | BF5: 26 | BG5: 28 | BH5: 38 | BI5: 20 | BJ5: =BE5+BF5+BG5+BH5+BI5 -> 117 | BL5: 330 | BM5: 18/1 | BN5: 70 | BO5: 72 | BP5: 60 | BQ5: 8 | BR5: 15 | BS5: =BN5+BO5+BP5+BQ5+BR5 -> 225 | BU5: 382 | BV5: 17/1 | BW5: 53 | BX5: 77 | BY5: 59 | BZ5: 20 | CA5: 7 | CB5: =BW5+BX5+BY5+BZ5+CA5 -> 216 | CD5: 434 | CE5: 16/1 | CF5: 13 | CG5: 76 | CH5: 26 | CI5: 67 | CJ5: 53 | CK5: =CF5+CG5+CH5+CI5+CJ5 -> 235 | CM5: 486 | CN5: 15/1 | CO5: 79 | CP5: 73 | CQ5: 52 | CR5: 35 | CS5: 17 | CT5: =CO5+CP5+CQ5+CR5+CS5 -> 256 | CV5: 539 | CW5: 20/1 | CX5: 17 | CY5: 61 | CZ5: 16 | DA5: 46 | DB5: 27 | DC5: =CX5+CY5+CZ5+DA5+DB5 -> 167 | DE5: 591 | DF5: 19/1 | DG5: 81 | DH5: 51 | DI5: 5 | DJ5: 88 | DK5: 58 | DL5: =DG5+DH5+DI5+DJ5+DK5 -> 283
A6: 4 | B6: 20/10 | C6: 23 | D6: 20 | E6: 90 | F6: 4 | G6: 63 | H6: =C6+D6+E6+F6+G6 -> 200 | J6: 18 | K6: 26/1 | L6: 88 | M6: 84 | N6: 28 | O6: 89 | P6: 2 | Q6: =L6+M6+N6+O6+P6 -> 291 | S6: 70 | T6: 25/1 | U6: 64 | V6: 70 | W6: 83 | X6: 56 | Y6: 75 | Z6: =U6+V6+W6+X6+Y6 -> 348 | AB6: 122 | AC6: 23/1 | AD6: 5 | AE6: 6 | AF6: 11 | AG6: 7 | AH6: 4 | AI6: =AD6+AE6+AF6+AG6+AH6 -> 33 | AK6: 174 | AL6: 22/1 | AM6: 67 | AN6: 11 | AO6: 90 | AP6: 59 | AQ6: 51 | AR6: =AM6+AN6+AO6+AP6+AQ6 -> 278 | AT6: 227 | AU6: 28/1 | AV6: 30 | AW6: 61 | AX6: 34 | AY6: 19 | AZ6: 75 | BA6: =AV6+AW6+AX6+AY6+AZ6 -> 219 | BC6: 279 | BD6: 27/1 | BE6: 60 | BF6: 61 | BG6: 76 | BH6: 16 | BI6: 6 | BJ6: =BE6+BF6+BG6+BH6+BI6 -> 219 | BL6: 331 | BM6: 25/1 | BN6: 61 | BO6: 26 | BP6: 86 | BQ6: 74 | BR6: 45 | BS6: =BN6+BO6+BP6+BQ6+BR6 -> 292 | BU6: 383 | BV6: 24/1 | BW6: 76 | BX6: 42 | BY6: 66 | BZ6: 48 | CA6: 86 | CB6: =BW6+BX6+BY6+BZ6+CA6 -> 318 | CD6: 435 | CE6: 23/1 | CF6: 23 | CG6: 22 | CH6: 82 | CI6: 79 | CJ6: 65 | CK6: =CF6+CG6+CH6+CI6+CJ6 -> 271 | CM6: 487 | CN6: 22/1 | CO6: 57 | CP6: 81 | CQ6: 29 | CR6: 12 | CS6: 76 | CT6: =CO6+CP6+CQ6+CR6+CS6 -> 255 | CV6: 540 | CW6: 27/1 | CX6: 13 | CY6: 33 | CZ6: 19 | DA6: 18 | DB6: 49 | DC6: =CX6+CY6+CZ6+DA6+DB6 -> 132 | DE6: 592 | DF6: 26/1 | DG6: 70 | DH6: 37 | DI6: 11 | DJ6: 19 | DK6: 73 | DL6: =DG6+DH6+DI6+DJ6+DK6 -> 210
A7: 5 | B7: 27/10 | C7: 71 | D7: 82 | E7: 12 | F7: 53 | G7: 86 | H7: =C7+D7+E7+F7+G7 -> 304 | J7: 19 | K7: 2/2 | L7: 42 | M7: 26 | N7: 76 | O7: 61 | P7: 39 | Q7: =L7+M7+N7+O7+P7 -> 244 | S7: 71 | T7: 1/2 | U7: 71 | V7: 44 | W7: 45 | X7: 25 | Y7: 57 | Z7: =U7+V7+W7+X7+Y7 -> 242 | AB7: 123 | AC7: 30/1 | AD7: 6 | AE7: 54 | AF7: 18 | AG7: 31 | AH7: 69 | AI7: =AD7+AE7+AF7+AG7+AH7 -> 178 | AK7: 175 | AL7: 29/1 | AM7: 63 | AN7: 17 | AO7: 12 | AP7: 87 | AQ7: 86 | AR7: =AM7+AN7+AO7+AP7+AQ7 -> 265 | AT7: 228 | AU7: 4/2 | AV7: 51 | AW7: 21 | AX7: 30 | AY7: 2 | AZ7: 87 | BA7: =AV7+AW7+AX7+AY7+AZ7 -> 191 | BC7: 280 | BD7: 3/2 | BE7: 34 | BF7: 79 | BG7: 53 | BH7: 75 | BI7: 31 | BJ7: =BE7+BF7+BG7+BH7+BI7 -> 272 | BL7: 332 | BM7: 1/2 | BN7: 24 | BO7: 79 | BP7: 5 | BQ7: 21 | BR7: 56 | BS7: =BN7+BO7+BP7+BQ7+BR7 -> 185 | BU7: 384 | BV7: 31/1 | BW7: 55 | BX7: 31 | BY7: 57 | BZ7: 26 | CA7: 28 | CB7: =BW7+BX7+BY7+BZ7+CA7 -> 197 | CD7: 436 | CE7: 30/1 | CF7: 39 | CG7: 11 | CH7: 81 | CI7: 44 | CJ7: 12 | CK7: =CF7+CG7+CH7+CI7+CJ7 -> 187 | CM7: 488 | CN7: 29/1 | CO7: 74 | CP7: 15 | CQ7: 71 | CR7: 45 | CS7: 53 | CT7: =CO7+CP7+CQ7+CR7+CS7 -> 258 | CV7: 541 | CW7: 3/2 | CX7: 3 | CY7: 50 | CZ7: 64 | DA7: 52 | DB7: 40 | DC7: =CX7+CY7+CZ7+DA7+DB7 -> 209 | DE7: 593 | DF7: 2/2 | DG7: 22 | DH7: 90 | DI7: 81 | DJ7: 82 | DK7: 49 | DL7: =DG7+DH7+DI7+DJ7+DK7 -> 324
A8: 6 | B8: 3/11 | C8: 28 | D8: 84 | E8: 50 | F8: 48 | G8: 52 | H8: =C8+D8+E8+F8+G8 -> 262 | J8: 20 | K8: 9/2 | L8: 77 | M8: 41 | N8: 32 | O8: 79 | P8: 8 | Q8: =L8+M8+N8+O8+P8 -> 237 | S8: 72 | T8: 8/2 | U8: 61 | V8: 28 | W8: 54 | X8: 21 | Y8: 12 | Z8: =U8+V8+W8+X8+Y8 -> 176 | AB8: 124 | AC8: 6/2 | AD8: 33 | AE8: 59 | AF8: 47 | AG8: 85 | AH8: 53 | AI8: =AD8+AE8+AF8+AG8+AH8 -> 277 | AK8: 176 | AL8: 5/2 | AM8: 28 | AN8: 86 | AO8: 89 | AP8: 36 | AQ8: 20 | AR8: =AM8+AN8+AO8+AP8+AQ8 -> 259 | AT8: 229 | AU8: 11/2 | AV8: 79 | AW8: 56 | AX8: 32 | AY8: 16 | AZ8: 28 | BA8: =AV8+AW8+AX8+AY8+AZ8 -> 211 | BC8: 281 | BD8: 10/2 | BE8: 69 | BF8: 74 | BG8: 51 | BH8: 38 | BI8: 71 | BJ8: =BE8+BF8+BG8+BH8+BI8 -> 303 | BL8: 333 | BM8: 8/2 | BN8: 33 | BO8: 74 | BP8: 78 | BQ8: 11 | BR8: 90 | BS8: =BN8+BO8+BP8+BQ8+BR8 -> 286 | BU8: 385 | BV8: 7/2 | BW8: 77 | BX8: 51 | BY8: 55 | BZ8: 23 | CA8: 89 | CB8: =BW8+BX8+BY8+BZ8+CA8 -> 295 | CD8: 437 | CE8: 6/2 | CF8: 66 | CG8: 40 | CH8: 31 | CI8: 10 | CJ8: 22 | CK8: =CF8+CG8+CH8+CI8+CJ8 -> 169 | CM8: 489 | CN8: 5/2 | CO8: 74 | CP8: 51 | CQ8: 54 | CR8: 77 | CS8: 47 | CT8: =CO8+CP8+CQ8+CR8+CS8 -> 303 | CV8: 542 | CW8: 10/2 | CX8: 65 | CY8: 43 | CZ8: 68 | DA8: 63 | DB8: 21 | DC8: =CX8+CY8+CZ8+DA8+DB8 -> 260 | DE8: 594 | DF8: 9/2 | DG8: 74 | DH8: 13 | DI8: 47 | DJ8: 2 | DK8: 10 | DL8: =DG8+DH8+DI8+DJ8+DK8 -> 146
A9: 7 | B9: 10/11 | C9: 31 | D9: 37 | E9: 78 | F9: 24 | G9: 7 | H9: =C9+D9+E9+F9+G9 -> 177 | J9: 21 | K9: 16/2 | L9: 42 | M9: 70 | N9: 71 | O9: 9 | P9: 74 | Q9: =L9+M9+N9+O9+P9 -> 266 | S9: 73 | T9: 15/2 | U9: 29 | V9: 87 | W9: 85 | X9: 65 | Y9: 64 | Z9: =U9+V9+W9+X9+Y9 -> 330 | AB9: 125 | AC9: 13/2 | AD9: 57 | AE9: 13 | AF9: 80 | AG9: 83 | AH9: 30 | AI9: =AD9+AE9+AF9+AG9+AH9 -> 263 | AK9: 177 | AL9: 12/2 | AM9: 89 | AN9: 61 | AO9: 78 | AP9: 21 | AQ9: 80 | AR9: =AM9+AN9+AO9+AP9+AQ9 -> 329 | AT9: 230 | AU9: 18/2 | AV9: 31 | AW9: 67 | AX9: 88 | AY9: 71 | AZ9: 40 | BA9: =AV9+AW9+AX9+AY9+AZ9 -> 297 | BC9: 282 | BD9: 17/2 | BE9: 27 | BF9: 36 | BG9: 61 | BH9: 67 | BI9: 69 | BJ9: =BE9+BF9+BG9+BH9+BI9 -> 260 | BL9: 334 | BM9: 15/2 | BN9: 27 | BO9: 72 | BP9: 85 | BQ9: 25 | BR9: 77 | BS9: =BN9+BO9+BP9+BQ9+BR9 -> 286 | BU9: 386 | BV9: 14/2 | BW9: 7 | BX9: 42 | BY9: 45 | BZ9: 57 | CA9: 76 | CB9: =BW9+BX9+BY9+BZ9+CA9 -> 227 | CD9: 438 | CE9: 13/2 | CF9: 46 | CG9: 2 | CH9: 69 | CI9: 51 | CJ9: 28 | CK9: =CF9+CG9+CH9+CI9+CJ9 -> 196 | CM9: 490 | CN9: 12/2 | CO9: 12 | CP9: 44 | CQ9: 54 | CR9: 28 | CS9: 8 | CT9: =CO9+CP9+CQ9+CR9+CS9 -> 146 | CV9: 543 | CW9: 17/2 | CX9: 23 | CY9: 50 | CZ9: 41 | DA9: 48 | DB9: 75 | DC9: =CX9+CY9+CZ9+DA9+DB9 -> 237 | DE9: 595 | DF9: 16/2 | DG9: 22 | DH9: 38 | DI9: 46 | DJ9: 21 | DK9: 57 | DL9: =DG9+DH9+DI9+DJ9+DK9 -> 184
A10: 8 | B10: 17/11 | C10: 37 | D10: 71 | E10: 90 | F10: 13 | G10: 18 | H10: =C10+D10+E10+F10+G10 -> 229 | J10: 22 | K10: 23/2 | L10: 34 | M10: 39 | N10: 48 | O10: 22 | P10: 69 | Q10: =L10+M10+N10+O10+P10 -> 212 | S10: 74 | T10: 22/2 | U10: 87 | V10: 59 | W10: 83 | X10: 30 | Y10: 38 | Z10: =U10+V10+W10+X10+Y10 -> 297 | AB10: 126 | AC10: 20/2 | AD10: 32 | AE10: 3 | AF10: 69 | AG10: 48 | AH10: 54 | AI10: =AD10+AE10+AF10+AG10+AH10 -> 206 | AK10: 178 | AL10: 19/2 | AM10: 6 | AN10: 24 | AO10: 67 | AP10: 86 | AQ10: 31 | AR10: =AM10+AN10+AO10+AP10+AQ10 -> 214 | AT10: 231 | AU10: 25/2 | AV10: 51 | AW10: 33 | AX10: 73 | AY10: 42 | AZ10: 90 | BA10: =AV10+AW10+AX10+AY10+AZ10 -> 289 | BC10: 283 | BD10: 24/2 | BE10: 18 | BF10: 58 | BG10: 78 | BH10: 70 | BI10: 66 | BJ10: =BE10+BF10+BG10+BH10+BI10 -> 290 | BL10: 335 | BM10: 22/2 | BN10: 15 | BO10: 77 | BP10: 12 | BQ10: 87 | BR10: 62 | BS10: =BN10+BO10+BP10+BQ10+BR10 -> 253 | BU10: 387 | BV10: 21/2 | BW10: 10 | BX10: 4 | BY10: 85 | BZ10: 74 | CA10: 11 | CB10: =BW10+BX10+BY10+BZ10+CA10 -> 184 | CD10: 439 | CE10: 20/2 | CF10: 2 | CG10: 90 | CH10: 15 | CI10: 3 | CJ10: 67 | CK10: =CF10+CG10+CH10+CI10+CJ10 -> 177 | CM10: 491 | CN10: 19/2 | CO10: 53 | CP10: 56 | CQ10: 49 | CR10: 42 | CS10: 11 | CT10: =CO10+CP10+CQ10+CR10+CS10 -> 211 | CV10: 544 | CW10: 24/2 | CX10: 8 | CY10: 10 | CZ10: 23 | DA10: 3 | DB10: 89 | DC10: =CX10+CY10+CZ10+DA10+DB10 -> 133 | DE10: 596 | DF10: 23/2 | DG10: 7 | DH10: 81 | DI10: 76 | DJ10: 12 | DK10: 47 | DL10: =DG10+DH10+DI10+DJ10+DK10 -> 223
A11: 9 | B11: 24/11 | C11: 80 | D11: 40 | E11: 76 | F11: 66 | G11: 8 | H11: =C11+D11+E11+F11+G11 -> 270 | J11: 23 | K11: 2/3 | L11: 75 | M11: 52 | N11: 27 | O11: 1 | P11: 12 | Q11: =L11+M11+N11+O11+P11 -> 167 | S11: 75 | T11: 29/2 | U11: 71 | V11: 1 | W11: 73 | X11: 4 | Y11: 68 | Z11: =U11+V11+W11+X11+Y11 -> 217 | AB11: 127 | AC11: 27/2 | AD11: 77 | AE11: 53 | AF11: 32 | AG11: 13 | AH11: 80 | AI11: =AD11+AE11+AF11+AG11+AH11 -> 255 | AK11: 179 | AL11: 26/2 | AM11: 57 | AN11: 28 | AO11: 26 | AP11: 22 | AQ11: 82 | AR11: =AM11+AN11+AO11+AP11+AQ11 -> 215 | AT11: 232 | AU11: 4/3 | AV11: 60 | AW11: 14 | AX11: 19 | AY11: 38 | AZ11: 79 | BA11: =AV11+AW11+AX11+AY11+AZ11 -> 210 | BC11: 284 | BD11: 2/3 | BE11: 33 | BF11: 66 | BG11: 77 | BH11: 35 | BI11: 37 | BJ11: =BE11+BF11+BG11+BH11+BI11 -> 248 | BL11: 336 | BM11: 1/3 | BN11: 38 | BO11: 57 | BP11: 28 | BQ11: 70 | BR11: 90 | BS11: =BN11+BO11+BP11+BQ11+BR11 -> 283 | BU11: 388 | BV11: 28/2 | BW11: 21 | BX11: 59 | BY11: 72 | BZ11: 53 | CA11: 76 | CB11: =BW11+BX11+BY11+BZ11+CA11 -> 281 | CD11: 440 | CE11: 27/2 | CF11: 12 | CG11: 26 | CH11: 73 | CI11: 8 | CJ11: 40 | CK11: =CF11+CG11+CH11+CI11+CJ11 -> 159 | CM11: 492 | CN11: 26/2 | CO11: 17 | CP11: 6 | CQ11: 72 | CR11: 52 | CS11: 1 | CT11: =CO11+CP11+CQ11+CR11+CS11 -> 148 | CV11: 545 | CW11: 3/3 | CX11: 44 | CY11: 43 | CZ11: 90 | DA11: 11 | DB11: 18 | DC11: =CX11+CY11+CZ11+DA11+DB11 -> 206 | DE11: 597 | DF11: 2/3 | DG11: 81 | DH11: 44 | DI11: 12 | DJ11: 42 | DK11: 25 | DL11: =DG11+DH11+DI11+DJ11+DK11 -> 204
A12: 10 | B12: 1/12 | C12: 43 | D12: 90 | E12: 51 | F12: 61 | G12: 8 | H12: =C12+D12+E12+F12+G12 -> 253 | J12: 24 | K12: 9/3 | L12: 36 | M12: 51 | N12: 46 | O12: 23 | P12: 38 | Q12: =L12+M12+N12+O12+P12 -> 194 | S12: 76 | T12: 7/3 | U12: 44 | V12: 54 | W12: 28 | X12: 50 | Y12: 2 | Z12: =U12+V12+W12+X12+Y12 -> 178 | AB12: 128 | AC12: 6/3 | AD12: 8 | AE12: 29 | AF12: 39 | AG12: 15 | AH12: 28 | AI12: =AD12+AE12+AF12+AG12+AH12 -> 119 | AK12: 180 | AL12: 5/3 | AM12: 45 | AN12: 55 | AO12: 43 | AP12: 19 | AQ12: 53 | AR12: =AM12+AN12+AO12+AP12+AQ12 -> 215 | AT12: 233 | AU12: 11/3 | AV12: 58 | AW12: 2 | AX12: 60 | AY12: 42 | AZ12: 90 | BA12: =AV12+AW12+AX12+AY12+AZ12 -> 252 | BC12: 285 | BD12: 9/3 | BE12: 80 | BF12: 40 | BG12: 51 | BH12: 16 | BI12: 70 | BJ12: =BE12+BF12+BG12+BH12+BI12 -> 257 | BL12: 337 | BM12: 8/3 | BN12: 77 | BO12: 38 | BP12: 89 | BQ12: 65 | BR12: 75 | BS12: =BN12+BO12+BP12+BQ12+BR12 -> 344 | BU12: 389 | BV12: 7/3 | BW12: 73 | BX12: 41 | BY12: 28 | BZ12: 71 | CA12: 55 | CB12: =BW12+BX12+BY12+BZ12+CA12 -> 268 | CD12: 441 | CE12: 6/3 | CF12: 65 | CG12: 60 | CH12: 56 | CI12: 78 | CJ12: 49 | CK12: =CF12+CG12+CH12+CI12+CJ12 -> 308 | CM12: 493 | CN12: 4/3 | CO12: 21 | CP12: 87 | CQ12: 56 | CR12: 42 | CS12: 3 | CT12: =CO12+CP12+CQ12+CR12+CS12 -> 209 | CV12: 546 | CW12: 11/3 | CX12: 5 | CY12: 11 | CZ12: 55 | DA12: 26 | DB12: 31 | DC12: =CX12+CY12+CZ12+DA12+DB12 -> 128 | DE12: 598 | DF12: 9/3 | DG12: 35 | DH12: 46 | DI12: 28 | DJ12: 41 | DK12: 64 | DL12: =DG12+DH12+DI12+DJ12+DK12 -> 214
A13: 11 | B13: 8/12 | C13: 46 | D13: 53 | E13: 90 | F13: 12 | G13: 19 | H13: =C13+D13+E13+F13+G13 -> 220 | J13: 25 | K13: 16/3 | L13: 70 | M13: 45 | N13: 48 | O13: 46 | P13: 63 | Q13: =L13+M13+N13+O13+P13 -> 272 | S13: 77 | T13: 14/3 | U13: 74 | V13: 45 | W13: 43 | X13: 61 | Y13: 22 | Z13: =U13+V13+W13+X13+Y13 -> 245 | AB13: 129 | AC13: 13/3 | AD13: 81 | AE13: 28 | AF13: 62 | AG13: 87 | AH13: 78 | AI13: =AD13+AE13+AF13+AG13+AH13 -> 336 | AK13: 181 | AL13: 12/3 | AM13: 57 | AN13: 32 | AO13: 67 | AP13: 90 | AQ13: 2 | AR13: =AM13+AN13+AO13+AP13+AQ13 -> 248 | AT13: 234 | AU13: 18/3 | AV13: 25 | AW13: 69 | AX13: 82 | AY13: 39 | AZ13: 37 | BA13: =AV13+AW13+AX13+AY13+AZ13 -> 252 | BC13: 286 | BD13: 16/3 | BE13: 83 | BF13: 67 | BG13: 25 | BH13: 21 | BI13: 33 | BJ13: =BE13+BF13+BG13+BH13+BI13 -> 229 | BL13: 338 | BM13: 15/3 | BN13: 59 | BO13: 26 | BP13: 9 | BQ13: 17 | BR13: 72 | BS13: =BN13+BO13+BP13+BQ13+BR13 -> 183 | BU13: 390 | BV13: 14/3 | BW13: 19 | BX13: 59 | BY13: 25 | BZ13: 12 | CA13: 88 | CB13: =BW13+BX13+BY13+BZ13+CA13 -> 203 | CD13: 442 | CE13: 13/3 | CF13: 86 | CG13: 54 | CH13: 81 | CI13: 73 | CJ13: 72 | CK13: =CF13+CG13+CH13+CI13+CJ13 -> 366 | CM13: 494 | CN13: 11/3 | CO13: 41 | CP13: 7 | CQ13: 29 | CR13: 43 | CS13: 85 | CT13: =CO13+CP13+CQ13+CR13+CS13 -> 205 | CV13: 547 | CW13: 18/3 | CX13: 25 | CY13: 45 | CZ13: 73 | DA13: 55 | DB13: 71 | DC13: =CX13+CY13+CZ13+DA13+DB13 -> 269 | DE13: 599 | DF13: 16/3 | DG13: 32 | DH13: 54 | DI13: 19 | DJ13: 50 | DK13: 21 | DL13: =DG13+DH13+DI13+DJ13+DK13 -> 176
A14: 12 | B14: 15/12 | C14: 2 | D14: 44 | E14: 34 | F14: 9 | G14: 41 | H14: =C14+D14+E14+F14+G14 -> 130 | J14: 26 | K14: 23/3 | L14: 27 | M14: 12 | N14: 29 | O14: 42 | P14: 17 | Q14: =L14+M14+N14+O14+P14 -> 127 | S14: 78 | T14: 21/3 | U14: 82 | V14: 90 | W14: 32 | X14: 27 | Y14: 60 | Z14: =U14+V14+W14+X14+Y14 -> 291 | AB14: 130 | AC14: 20/3 | AD14: 66 | AE14: 3 | AF14: 83 | AG14: 75 | AH14: 71 | AI14: =AD14+AE14+AF14+AG14+AH14 -> 298 | AK14: 182 | AL14: 19/3 | AM14: 5 | AN14: 82 | AO14: 74 | AP14: 66 | AQ14: 88 | AR14: =AM14+AN14+AO14+AP14+AQ14 -> 315 | AT14: 235 | AU14: 25/3 | AV14: 50 | AW14: 38 | AX14: 7 | AY14: 46 | AZ14: 4 | BA14: =AV14+AW14+AX14+AY14+AZ14 -> 145 | BC14: 287 | BD14: 23/3 | BE14: 19 | BF14: 46 | BG14: 20 | BH14: 51 | BI14: 80 | BJ14: =BE14+BF14+BG14+BH14+BI14 -> 216 | BL14: 339 | BM14: 22/3 | BN14: 41 | BO14: 67 | BP14: 7 | BQ14: 22 | BR14: 18 | BS14: =BN14+BO14+BP14+BQ14+BR14 -> 155 | BU14: 391 | BV14: 21/3 | BW14: 70 | BX14: 47 | BY14: 86 | BZ14: 6 | CA14: 82 | CB14: =BW14+BX14+BY14+BZ14+CA14 -> 291 | CD14: 443 | CE14: 20/3 | CF14: 76 | CG14: 3 | CH14: 88 | CI14: 1 | CJ14: 4 | CK14: =CF14+CG14+CH14+CI14+CJ14 -> 172 | CM14: 495 | CN14: 18/3 | CO14: 20 | CP14: 11 | CQ14: 41 | CR14: 64 | CS14: 2 | CT14: =CO14+CP14+CQ14+CR14+CS14 -> 138 | CV14: 548 | CW14: 24/3 | CX14: 33 | CY14: 11 | CZ14: 27 | DA14: 86 | DB14: 79 | DC14: =CX14+CY14+CZ14+DA14+DB14 -> 236 | DE14: 600 | DF14: 23/3 | DG14: 46 | DH14: 10 | DI14: 29 | DJ14: 55 | DK14: 77 | DL14: =DG14+DH14+DI14+DJ14+DK14 -> 217
... A16: 14 | B16: 29/12 | C16: 89 | D16: 18 | E16: 66 | F16: 44 | G16: 46 | H16: =C16+D16+E16+F16+G16 -> 263 | J16: 28 | K16: 6/4 | L16: 44 | M16: 72 | N16: 76 | O16: 26 | P16: 2 | Q16: =L16+M16+N16+O16+P16 -> 220 | S16: 80 | T16: 4/4 | U16: 26 | V16: 87 | W16: 55 | X16: 47 | Y16: 16 | Z16: =U16+V16+W16+X16+Y16 -> 231 | AB16: 132 | AC16: 3/4 | AD16: 84 | AE16: 87 | AF16: 77 | AG16: 44 | AH16: 53 | AI16: =AD16+AE16+AF16+AG16+AH16 -> 345 | AK16: 184 | AL16: 2/4 | AM16: 30 | AN16: 44 | AO16: 77 | AP16: 4 | AQ16: 24 | AR16: =AM16+AN16+AO16+AP16+AQ16 -> 179 | AT16: 237 | AU16: 8/4 | AV16: 81 | AW16: 85 | AX16: 36 | AY16: 41 | AZ16: 90 | BA16: =AV16+AW16+AX16+AY16+AZ16 -> 333 | BC16: 289 | BD16: 6/4 | BE16: 29 | BF16: 65 | BG16: 45 | BH16: 66 | BI16: 70 | BJ16: =BE16+BF16+BG16+BH16+BI16 -> 275 | BL16: 341 | BM16: 5/4 | BN16: 75 | BO16: 76 | BP16: 37 | BQ16: 56 | BR16: 80 | BS16: =BN16+BO16+BP16+BQ16+BR16 -> 324 | BU16: 393 | BV16: 4/4 | BW16: 13 | BX16: 80 | BY16: 67 | BZ16: 68 | CA16: 20 | CB16: =BW16+BX16+BY16+BZ16+CA16 -> 248 | CD16: 445 | CE16: 3/4 | CF16: 39 | CG16: 47 | CH16: 64 | CI16: 80 | CJ16: 23 | CK16: =CF16+CG16+CH16+CI16+CJ16 -> 253 | CM16: 497 | CN16: 1/4 | CO16: 49 | CP16: 89 | CQ16: 67 | CR16: 22 | CS16: 31 | CT16: =CO16+CP16+CQ16+CR16+CS16 -> 258 | CV16: 550 | CW16: 7/4 | CX16: 69 | CY16: 44 | CZ16: 3 | DA16: 9 | DB16: 87 | DC16: =CX16+CY16+CZ16+DA16+DB16 -> 212 | DE16: 602 | DF16: 6/4 | DG16: 87 | DH16: 89 | DI16: 56 | DJ16: 3 | DK16: 1 | DL16: =DG16+DH16+DI16+DJ16+DK16 -> 236
J17: 29 | K17: 13/4 | L17: 39 | M17: 3 | N17: 5 | O17: 43 | P17: 4 | Q17: =L17+M17+N17+O17+P17 -> 94 | S17: 81 | T17: 11/4 | U17: 50 | V17: 28 | W17: 61 | X17: 40 | Y17: 62 | Z17: =U17+V17+W17+X17+Y17 -> 241 | AB17: 133 | AC17: 10/4 | AD17: 9 | AE17: 83 | AF17: 23 | AG17: 38 | AH17: 78 | AI17: =AD17+AE17+AF17+AG17+AH17 -> 231 | AK17: 185 | AL17: 9/4 | AM17: 13 | AN17: 44 | AO17: 33 | AP17: 51 | AQ17: 62 | AR17: =AM17+AN17+AO17+AP17+AQ17 -> 203 | AT17: 238 | AU17: 15/4 | AV17: 71 | AW17: 86 | AX17: 9 | AY17: 64 | AZ17: 14 | BA17: =AV17+AW17+AX17+AY17+AZ17 -> 244 | BC17: 290 | BD17: 13/4 | BE17: 80 | BF17: 85 | BG17: 87 | BH17: 72 | BI17: 34 | BJ17: =BE17+BF17+BG17+BH17+BI17 -> 358 | BL17: 342 | BM17: 12/4 | BN17: 2 | BO17: 83 | BP17: 25 | BQ17: 11 | BR17: 19 | BS17: =BN17+BO17+BP17+BQ17+BR17 -> 140 | BU17: 394 | BV17: 11/4 | BW17: 8 | BX17: 2 | BY17: 20 | BZ17: 13 | CA17: 85 | CB17: =BW17+BX17+BY17+BZ17+CA17 -> 128 | CD17: 446 | CE17: 10/4 | CF17: 64 | CG17: 73 | CH17: 16 | CI17: 49 | CJ17: 27 | CK17: =CF17+CG17+CH17+CI17+CJ17 -> 229 | CM17: 498 | CN17: 8/4 | CO17: 50 | CP17: 65 | CQ17: 17 | CR17: 22 | CS17: 34 | CT17: =CO17+CP17+CQ17+CR17+CS17 -> 188 | CV17: 551 | CW17: 14/4 | CX17: 79 | CY17: 81 | CZ17: 72 | DA17: 82 | DB17: 33 | DC17: =CX17+CY17+CZ17+DA17+DB17 -> 347 | DE17: 603 | DF17: 13/4 | DG17: 67 | DH17: 4 | DI17: 58 | DJ17: 84 | DK17: 78 | DL17: =DG17+DH17+DI17+DJ17+DK17 -> 291
